Workbook

Sheet Start
E6: MM HOLDING GMBH · UNTERNEHMERISCHE BETEILIGUNGEN · WEINGARTEN | G6: ERSTELLT FÜR
E7: =Obj_Name -> Beispiel: 3-Zimmer-Eigentumswohnung | G7: Max Mustermann
E9: Immobilien-Kalkulation
E11: Kauf · Finanzierung · Cashflow · Steuern · Exit — für vermietete Immobilien im Privatvermögen oder in der GmbH
E12: ="Stand "&TEXT(DAY(TODAY()),"00")&"."&TEXT(MONTH(TODAY()),"00")&"."&YEAR(TODAY())&" · Rechtsstand September 2026 · Kauf als: "&CHOOSE(Rechtsform_Idx,"Privatperson","vv-GmbH","GmbH / Holding") -> Stand 24.09.2026 · Rechtsstand September 2026 · Kauf als: Privatperson
E14: GESAMTINVESTITION | F14: KAUFPREIS | G14: HALTEDAUER
E15: =Gesamtinvestition -> 328974.5 | F15: =Kaufpreis -> 285000 | G15: =Haltedauer -> 12
E17: Zuerst: Kauf als wählen ↓ | F17: Leitfaden starten ›
C21: Kauf als – Privatperson oder Gesellschaft | G21: Pflichtauswahl
C23: KAUF ALS ▾ Auswahlliste | D23: Privatperson – Einkünfte aus Vermietung und Verpachtung (§ 21 EStG) | G23: Auswahl ändern ▾
D24: ▾ Klicken und aus der Liste wählen: Privatperson · vv-GmbH · gewerbliche GmbH/Holding · wirkt auf S09 Steuern, S11 Exit, Dashboard und Bankgespräch
C26: Aktuelle Kalkulation im Überblick | G26: Details im Dashboard ›
C27: CASHFLOW N. ST. / MONAT (JAHR 1) | E27: BRUTTOMIETRENDITE | F27: DSCR | G27: =UPPER("IRR n. St. ("&Haltedauer&" J.)") -> IRR N. ST. (12 J.)
C28: =CF_nSt_Monat_J1 -> 256.53305 | E28: =Bruttomietrendite -> 0.04 | F28: =DSCR_J1 -> 0.612 | G28: =EK_IRR -> 0.053273956
C29: ="Jahr 2: "&SUBSTITUTE(FIXED(INDEX(Projektion!$D$37:$AQ$37,2),0),"-","−")&" €" -> Jahr 2: −274 € | D29: =IF(CF_nSt_Monat_J1<0,"● kritisch",IF(INDEX(Projektion!$D$37:$AQ$37,2)<0,"● prüfen",IF(ISNUMBER(CF_nSt_Monat_J1),"● erfüllt",""))) -> ● prüfen | E29: ="Ziel ≥ "&FIXED(Ampel_BMR_gruen*100,1)&" %" -> Ziel ≥ 5.0 % | F29: ="Jahr 1 · "&"Ziel ≥ "&FIXED(Ampel_DSCR_gruen,2)&"×" -> Jahr 1 · Ziel ≥ 1.20× | G29: ="Ziel ≥ "&FIXED(Ampel_IRR_gruen*100,1)&" %" -> Ziel ≥ 6.0 %
C30: Cashflow nach Steuern pro Monat (Jahr 1) | E30: DSCR (Jahr 1) | F30: ="IRR n. St. – Verkauf nach "&Haltedauer&" J." -> IRR n. St. – Verkauf nach 12 J. | G30: Rechtsform | AfA
C31: =CF_nSt_Monat_J1 -> 256.53305 | E31: =DSCR_J1 -> 0.612 | F31: =EK_IRR -> 0.053273956 | G31: =CHOOSE(Rechtsform_Idx,"Privat","vv-GmbH","GmbH")&" | "&CHOOSE(Methode_eff,"nach Baujahr","linear 2 %","linear 2,5 %","linear 3 %","degressiv","Gutachten") -> Privat | nach Baujahr
C34: Ihr Weg durch das Tool | G34: 6 Etappen · A–F
C35: A Kauf als wählen › | E35: Privatperson oder Gesellschaft – die Auswahl oben steuert Steuern, Exit und Bankunterlagen.
C36: B Leitfaden: Schritte 01–12 › | E36: Vom Objekt bis zum Ergebnis – jede Seite mit Eingaben, Zwischenergebnis und Einordnung.
C37: C Dashboard › | E37: Die Gesamtbewertung auf einer Seite: Kennzahlen mit Status, Cashflow und Vermögen.
C38: D Cockpit & Diagramme › | E38: Detailkennzahlen und Prüfhinweise im Cockpit, alle Auswertungen als Diagramm.
C39: E Sensitivität › | E39: Break-even-Miete und -Zins, Miete × Zins und IRR-Matrix – wie robust ist die Rechnung?
C40: F Bankunterlagen › | E40: Bankgespräch als A4-Übersicht, dazu Haushaltsrechnung und Vermögensaufstellung.
C46: Legende | F46: Alle Blätter | G46: Schritte S01–S12: siehe Leitfaden
C48: Eingabe | D48: Gelb hinterlegt – hier eingeben, Beispielwerte überschreiben | F48: Leitfaden › | G48: Zwölf Schritte vom Objekt zum Ergebnis
C49: Verknüpfung | D49: Blau – übernommen aus einer Eingabe an anderer Stelle | F49: Dashboard › | G49: Gesamtbewertung auf einer Seite
C50: Berechnung | D50: Schwarz – berechnet, bitte nicht ändern | F50: Cockpit › | G50: Detailkennzahlen und Prüfhinweise
C51: Ergebnis | D51: Hervorgehoben – Summe bzw. Blockergebnis | F51: Diagramme › | G51: 13 Diagramme zur Kalkulation
C52: −1.234 € | D52: Rot – negative Ergebnis- und Kumulwerte | F52: Eingaben › | G52: Alle Eingaben und Profi-Felder
C53: Status | D53: ● erfüllt · ● prüfen · ● kritisch | F53: Projektion › | G53: Miete, Kosten, Vermögen – 40 Jahre
C54: Prüfhinweis | D54: ▲ Warnung ⓘ Information | F54: Steuern › | G54: Steuerparameter, AfA, Ergebnis, Exit
C55: Blattschutz | D55: ohne Passwort – bei Bedarf aufheben | F55: AfA-Vergleich › | G55: Abschreibungsvarianten im Vergleich
C56: Navigation | D56: Reiter oben · „Weiter ›“ führt zum nächsten Schritt | F56: Finanzierung › | G56: Tilgungspläne Darlehen I und II
F57: Sensitivität › | G57: Break-even, Miete × Zins, IRR-Matrix
C58: Tipp & Support | F58: Bankgespräch › | G58: Investitionsübersicht für die Bank
C59: Beispielwerte in den gelben Feldern einfach überschreiben – alle Blätter rechnen sofort mit. Hilfe zu jedem Eingabefeld: Zelle markieren – der Eingabehinweis erscheint. Jedes Blatt ist für den Druck auf A4 eingerichtet. Blattwechsel per Tastatur: Strg + Bild ↓ / Bild ↑. Version Pro · Rechtsstand September 2026 · MM Holding GmbH, Weingarten | F59: Haushaltsrechnung › | G59: Selbstauskunft Einnahmen/Ausgaben
F60: Vermögensaufstellung › | G60: Selbstauskunft Vermögen
F61: Hinweise › | G61: Rechtsgrundlagen und Modellannahmen
F62: Konfiguration › | G62: Stammdaten, Tarif 2026, Ampel-Schwellen
...

Sheet Leitfaden
C5: EINSTIEG › IN ZWÖLF SCHRITTEN ZUR INVESTITIONSENTSCHEIDUNG | I5: ‹ Start
C6: Leitfaden | H6: Schritt 01 starten ›
C7: Hinweis Gelbe Felder enthalten Beispielwerte – einfach überschreiben. „Kauf als“ wählen Sie auf der Startseite. | F7: Kauf als wählen ›
C9: GESAMTINVESTITION | E9: EIGENKAPITALBEDARF INKL. RESERVE | F9: RATE AN DIE BANK / MONAT | H9: CASHFLOW N. ST. / MONAT (JAHR 1)
C10: =Gesamtinvestition -> 328974.5 | E10: =EK_Bedarf_gesamt -> 83974.5 | F10: =Kapitaldienst_Monat_J1 -> 1166.6667 | H10: =CF_nSt_Monat_J1 -> 256.53305
C11: ="Kaufpreis "&FIXED(Kaufpreis,0)&" € · NK "&FIXED(NK_Quote*100,1)&" %" -> Kaufpreis 285,000 € · NK 10.6 % | E11: ="Quote "&FIXED(EK_Quote*100,1)&" % · Beleihung "&FIXED(Beleihung*100,1)&" %" -> Quote 24.0 % · Beleihung 87.7 % | F11: ="Volltilgung "&Volltilgung_Txt -> Volltilgung Jahr 32 (2057) | H11: ="Jahr 2: "&SUBSTITUTE(FIXED(INDEX(Projektion!$D$37:$AQ$37,2),0),"-","−")&" €" -> Jahr 2: −274 € | I11: =IF(CF_nSt_Monat_J1<0,"● kritisch",IF(INDEX(Projektion!$D$37:$AQ$37,2)<0,"● prüfen",IF(ISNUMBER(CF_nSt_Monat_J1),"● erfüllt",""))) -> ● prüfen
C12: Cashflow vor Steuern pro Monat (Jahr 1) | E12: Bruttomietrendite | F12: DSCR (Jahr 1) | H12: ="Eigenkapitalrendite p. a. (IRR) – Verkauf nach "&Haltedauer&" J." -> Eigenkapitalrendite p. a. (IRR) – Verkauf nach 12 J.
C13: =CF_vSt_J1/12 -> -452.66667 | E13: =Bruttomietrendite -> 0.04 | F13: =DSCR_J1 -> 0.612 | H13: =EK_IRR -> 0.053273956
C16: Die zwölf Schritte | F16: ✓ vollständig ○ Angaben fehlen
C17: STATUS | D17: SCHRITT | E17: INHALT
C18: =IF(AND(Wohnflaeche>0,Baujahr>0),"✓","○") -> ✓ | D18: 01 Objekt › | E18: Objektdaten, Baujahr, Kaufdatum und Bundesland – die Basis für Grunderwerbsteuer und AfA.
C19: =IF(AND(Kaufpreis>0,Miete_Monat>0),"✓","○") -> ✓ | D19: 02 Kaufpreis & Miete › | E19: Kaufpreis und Nettokaltmiete ergeben die erste Kennzahl: die Bruttomietrendite.
C20: =IF(NK_Summe>0,"✓","○") -> ✓ | D20: 03 Kaufnebenkosten › | E20: Grunderwerbsteuer, Notar, Grundbuch und Makler – sie erhöhen die AfA-Basis.
C21: =IF(AK_Gebaeude>0,"✓","○") -> ✓ | D21: 04 Kaufpreisaufteilung › | E21: Nur der Gebäudeanteil ist abschreibbar – Aufteilung in Grund und Boden und Gebäude.
C22: optional | D22: 05 Maßnahmen & Reserve › | E22: Renovierung, Sonderumlagen und Liquiditätsreserve – inklusive Prüfung der 15 %-Grenze.
C23: =IF(Hausgeld+Verwaltung_Monat+IH_Ruecklage_qm>0,"✓","○") -> ✓ | D23: 06 Bewirtschaftung › | E23: Hausgeld, Verwaltung, Rücklagen und Mietausfall – was von der Miete monatlich übrig bleibt.
C24: =IF(Darlehen_Summe>0,"✓","○") -> ✓ | D24: 07 Finanzierung › | E24: Darlehen, Zins, Tilgung und Zinsbindung – Rate, Eigenkapital und Restschuld.
C25: =IF(Darlehen_Summe>0,"✓","○") -> ✓ | D25: 08 Zwischenergebnis › | E25: Cashflow vor Steuern: Miete abzüglich Bewirtschaftung, Zinsen und Tilgung.
C26: =IF(OR(Rechtsform_Idx>1,zvE>0),"✓","○") -> ✓ | D26: 09 Steuern › | E26: Kauf als, Einkommen, Soli und Kirchensteuer – daraus folgt der angewendete Steuersatz.
C27: =IF(AfA_J1>0,"✓","○") -> ✓ | D27: 10 Abschreibung › | E27: AfA-Methode, Sonder-AfA § 7b und erhöhte Absetzungen § 7h/7i – der steuerliche Hebel.
C28: =IF(Haltedauer>0,"✓","○") -> ✓ | D28: 11 Prognose & Exit › | E28: Miet-, Kosten- und Wertsteigerung, Haltedauer und Verkauf – inklusive 10-Jahres-Frist.
C29: =IF(COUNTIF(C18:C28,"○")>0,"○","✓") -> ✓ | D29: 12 Ergebnis › | E29: Cashflow nach Steuern, Eigenkapitalrendite, Vermögensaufbau und Rente nach Volltilgung.
C31: Zum Dashboard › | H31: Schritt 01 starten ›
C33: Keine Gewähr für die Richtigkeit der Angaben · ersetzt keine Rechts-, Steuer- oder Finanzberatung · Rechtsstand September 2026
C34: MM Holding GmbH · Kornhausgasse 4 · 88250 Weingarten · Amtsgericht Ulm HRB 750729

Sheet S01 Objekt
C5: SCHRITT 01 / 12 · OBJEKT | I5: ‹ Leitfaden
C6: Objekt | H6: =Obj_Name -> Beispiel: 3-Zimmer-Eigentumswohnung
C7: Was wird gekauft? Objektdaten, Baujahr, Kaufdatum und Bundesland – die Basis für Grunderwerbsteuer und Abschreibung. | H7: =Obj_Adresse&IFERROR(IF(Erstellt_fuer="",""," · Erstellt für "&Erstellt_fuer),"") -> Musterstraße 1, 88250 Weingarten · Erstellt für Max Mustermann
C10: Eingaben | H10: Ergebnis dieses Schritts | I10: beim Kauf
C11: POSITION | D11: EINGABE | E11: EINHEIT | F11: HINWEIS | H11: Grunderwerbsteuersatz (Bundesland) | I11: =GrESt_Satz -> 0.05
C12: Objektbezeichnung | D12: Beispiel: 3-Zimmer-Eigentumswohnung | F12: Freitext – erscheint im Cockpit und im Bankgespräch | H12: Regulärer AfA-Satz nach Baujahr | I12: =AfA_Satz_auto -> 0.02
C13: Adresse | D13: Musterstraße 1, 88250 Weingarten | H13: Erstes Kalkulationsjahr | I13: =YEAR(Kaufdatum) -> 2026
C14: Objektart | D14: Eigentumswohnung | F14: Gewerbe: keine § 7b-Sonder-AfA, keine degressive AfA | H14: Wohngebäude (steuerlich) | I14: =IF(Wohngebaeude=1,"Ja","Nein (Gewerbe)") -> Ja
C15: Wohn-/Nutzfläche | D15: 75 | F15: Basis für Miete/m², Rücklage und § 7b-Grenzen
C16: Grundstücksfläche bzw. -anteil | D16: 120 | F16: ETW: Miteigentumsanteil × Fläche (Teilungserklärung) | H16: AfA nach Baujahr
C17: Baujahr (Fertigstellung) | D17: 1996 | F17: steuert den AfA-Satz und die Prüfung von § 7b | H17: =IF(Baujahr>=2023,"Neubau (Fertigstellung ab 2023): 3 % lineare AfA. Degressive AfA (5 % vom Restwert) und die Sonder-AfA § 7b (5 % p. a., 4 Jahre) stehen in Schritt 10 zur Wahl – sofern Baubeginn, Effizienzstandard und Baukostengrenze passen.",IF(Baujahr<1925,"Altbau (vor 1925): 2,5 % lineare AfA. Bei Baudenkmalen oder Sanierungsgebieten können erhöhte Absetzungen nach § 7h/7i EStG hinzukommen (Schritt 10).","Bestandsobjekt: 2 % lineare AfA. Eine kürzere Restnutzungsdauer lässt sich nur mit einem Sachverständigengutachten durchsetzen (Schritt 10).")) -> Bestandsobjekt: 2 % lineare AfA. Eine kürzere Restnutzungsdauer lässt sich nur mit einem Sachverständigengutachten durchsetzen (Schritt 10).
C18: Kaufdatum (Nutzen und Lasten) | D18: 46357 | F18: Jahr 1 = die ersten 12 Monate ab Kauf
C19: Bundesland (Belegenheit) | D19: Baden-Württemberg | F19: steuert den Grunderwerbsteuersatz
H20: ALS NÄCHSTES | I20: Schritt 02 / 12
C21: Hinweis Alle gelben Felder enthalten Beispielwerte – einfach überschreiben. | F21: Kauf als auf der Startseite wählen › | H21: Kaufpreis & Miete · Kaufpreis und Nettokaltmiete ergeben die erste Kennzahl: die Bruttomietrendite.
C25: ‹ Zurück: Start (Kauf als) | E25: Übersicht: Leitfaden | H25: Weiter: Kaufpreis & Miete ›
C27: Keine Gewähr für die Richtigkeit der Angaben · ersetzt keine Rechts-, Steuer- oder Finanzberatung · Rechtsstand September 2026
C28: MM Holding GmbH · Kornhausgasse 4 · 88250 Weingarten · Amtsgericht Ulm HRB 750729

Sheet S02 Kaufpreis & Miete
C5: SCHRITT 02 / 12 · KAUFPREIS & MIETE | I5: ‹ Leitfaden
C6: Kaufpreis & Miete | H6: =Obj_Name -> Beispiel: 3-Zimmer-Eigentumswohnung
C7: Kaufpreis und Nettokaltmiete ergeben die erste Kennzahl: die Bruttomietrendite. | H7: =Obj_Adresse&IFERROR(IF(Erstellt_fuer="",""," · Erstellt für "&Erstellt_fuer),"") -> Musterstraße 1, 88250 Weingarten · Erstellt für Max Mustermann
C10: Eingaben | H10: Ergebnis dieses Schritts | I10: Kauf · Jahr 1
C11: POSITION | D11: EINGABE | E11: EINHEIT | F11: HINWEIS | H11: Kaufpreis ohne Inventar/Rücklage | I11: =KP_Immobilie -> 274000
C12: Kaufpreis (gesamt lt. Kaufvertrag) | D12: 285000 | F12: inkl. beweglicher Gegenstände und Rücklagenanteil | H12: Kaufpreis je m² | I12: =IF(Wohnflaeche>0,KP_Immobilie/Wohnflaeche,0) -> 3653.3333
C13: davon bewegliche Gegenstände | D13: 8000 | F13: Küche, Möbel · grunderwerbsteuerfrei (§ 2 GrEStG) | H13: Nettokaltmiete je m² | I13: =Miete_qm -> 12.666667
C14: Nutzungsdauer der Gegenstände | D14: 10 | F14: Küche i. d. R. 10 Jahre, Möbel 8–13 (AfA-Tabelle) | H14: Kaufpreisfaktor | I14: =Kaufpreisfaktor -> 25
C15: davon Anteil Erhaltungsrücklage | D15: 3000 | F15: nicht abschreibbar, aber grunderwerbsteuerpflichtig | H15: = Bruttomietrendite | I15: =Bruttomietrendite -> 0.04
C16: Nettokaltmiete | D16: 950 | E16: pro Monat | F16: Soll-Miete lt. Mietvertrag bzw. Marktmiete | H16: nachrichtlich: Warmmiete pro Monat | I16: =Miete_Monat+NK_umlagefaehig -> 1170
C17: Umlagefähige Betriebskosten | D17: 220 | E17: pro Monat | F17: Vorauszahlung des Mieters · Durchlaufposten
H18: Bruttomietrendite | I18: =IF(AND(ISNUMBER(Bruttomietrendite),Bruttomietrendite<Ampel_BMR_gelb),"● kritisch"&" · "&FIXED(Bruttomietrendite*100,1)&" %",IF(AND(ISNUMBER(Bruttomietrendite),Bruttomietrendite<Ampel_BMR_gruen),"● prüfen"&" · "&FIXED(Bruttomietrendite*100,1)&" %",IF(ISNUMBER(Bruttomietrendite),"● erfüllt"&" · "&FIXED(Bruttomietrendite*100,1)&" %",""))) -> ● prüfen · 4.0 %
H19: =IF(Bruttomietrendite<Ampel_BMR_gelb,"Unter "&FIXED(Ampel_BMR_gelb*100,1)&" % trägt sich das Objekt aus der Miete allein meist nicht – bei üblicher Finanzierung wird der Cashflow vor Steuern negativ. Es rechnet sich dann nur über Tilgung, Wertentwicklung und Steuereffekte.",IF(Bruttomietrendite<Ampel_BMR_gruen,"Ausbaufähig: Solide ist eine Bruttomietrendite ab "&FIXED(Ampel_BMR_gruen*100,1)&" %, zwischen "&FIXED(Ampel_BMR_gelb*100,1)&" und "&FIXED(Ampel_BMR_gruen*100,1)&" % trägt sich die Finanzierung meist nur mit mehr Eigenkapital. Ob der Cashflow reicht, zeigen die Schritte 6 bis 10.","Solide: Das Ziel von "&FIXED(Ampel_BMR_gruen*100,1)&" % ist erreicht. Ob der Cashflow nach Kapitaldienst und Steuern positiv ist, entscheidet sich in den Schritten 6 bis 10.")) -> Ausbaufähig: Solide ist eine Bruttomietrendite ab 5.0 %, zwischen 4.0 und 5.0 % trägt sich die Finanzierung meist nur mit mehr Eigenkapital. Ob der Cashflow reicht, zeigen die Schritte 6 bis 10.
H21: ALS NÄCHSTES | I21: Schritt 03 / 12
H22: Kaufnebenkosten · Grunderwerbsteuer, Notar, Grundbuch und Makler – sie erhöhen die Anschaffungskosten und damit die AfA-Basis.
C25: ‹ Zurück: Objekt | E25: Übersicht: Leitfaden | H25: Weiter: Kaufnebenkosten ›
C27: Keine Gewähr für die Richtigkeit der Angaben · ersetzt keine Rechts-, Steuer- oder Finanzberatung · Rechtsstand September 2026
C28: MM Holding GmbH · Kornhausgasse 4 · 88250 Weingarten · Amtsgericht Ulm HRB 750729

Sheet S03 Kaufnebenkosten
C5: SCHRITT 03 / 12 · KAUFNEBENKOSTEN | I5: ‹ Leitfaden
C6: Kaufnebenkosten | H6: =Obj_Name -> Beispiel: 3-Zimmer-Eigentumswohnung
C7: Grunderwerbsteuer, Notar, Grundbuch und Makler – sie erhöhen die Anschaffungskosten und damit die AfA-Basis. | H7: =Obj_Adresse&IFERROR(IF(Erstellt_fuer="",""," · Erstellt für "&Erstellt_fuer),"") -> Musterstraße 1, 88250 Weingarten · Erstellt für Max Mustermann
C10: Eingaben | H10: Ergebnis dieses Schritts | I10: beim Kauf
C11: POSITION | D11: EINGABE | E11: EINHEIT | F11: HINWEIS | H11: Grunderwerbsteuer | I11: =GrESt_Betrag -> 13850
C12: Grunderwerbsteuer abweichend | F12: optional · leer = Satz des Bundeslands (siehe Ergebnis) | H12: Notar | I12: =Notar_Betrag -> 4275
C13: Notar (Kaufvertrag, Auflassung) | D13: 0.015 | F13: üblich 1,0 – 1,5 % des Kaufpreises | H13: Grundbuch | I13: =Grundbuch_Betrag -> 1425
C14: Grundbuchamt (Umschreibung) | D14: 0.005 | F14: üblich ca. 0,5 % | H14: Makler | I14: =Makler_Betrag -> 10174.5
C15: Maklerprovision (inkl. USt) | D15: 0.0357 | F15: z. B. 3,57 % (3 % zzgl. 19 % USt) | H15: Sonstige | I15: =NK_Sonst -> 500
C16: Sonstige Erwerbsnebenkosten | D16: 500 | F16: Gutachten, Fahrten – sofern objektbezogen | H16: = Summe Kaufnebenkosten | I16: =NK_Summe -> 30224.5
H17: Kaufnebenkostenquote | I17: =NK_Quote -> 0.10605088
C18: ZUSAMMENSETZUNG DER KAUFNEBENKOSTEN | F18: Anteile in % | H18: = Anschaffungskosten gesamt | I18: =AK_Gesamt -> 315224.5
H20: Steuerliche Behandlung
H21: Kaufnebenkosten sind Anschaffungsnebenkosten: kein Sofortabzug, sondern Verteilung über die AfA – anteilig nach dem Gebäudeanteil (Schritt 4). Gesondert ausgewiesene bewegliche Gegenstände mindern die Bemessungsgrundlage der Grunderwerbsteuer.
H23: KAUFNEBENKOSTEN GESAMT
H24: =NK_Summe -> 30224.5
H25: =IFERROR("je m² Wohnfläche: "&FIXED(NK_Summe/Wohnflaeche,0)&" €","") -> je m² Wohnfläche: 403 €
H27: ALS NÄCHSTES | I27: Schritt 04 / 12
H28: Kaufpreisaufteilung · Nur der Gebäudeanteil ist abschreibbar – die Aufteilung zwischen Grund und Boden und Gebäude.
C31: ‹ Zurück: Kaufpreis & Miete | E31: Übersicht: Leitfaden | H31: Weiter: Kaufpreisaufteilung ›
C33: Keine Gewähr für die Richtigkeit der Angaben · ersetzt keine Rechts-, Steuer- oder Finanzberatung · Rechtsstand September 2026
C34: MM Holding GmbH · Kornhausgasse 4 · 88250 Weingarten · Amtsgericht Ulm HRB 750729
C60: DIAGRAMMDATEN (AUTOMATISCH)
C61: Grunderwerbsteuer | D61: =GrESt_Betrag -> 13850
C62: Notar | D62: =Notar_Betrag -> 4275
C63: Grundbuch | D63: =Grundbuch_Betrag -> 1425
C64: Makler | D64: =Makler_Betrag -> 10174.5
C65: Sonstige | D65: =NK_Sonst -> 500

Sheet S04 Kaufpreisaufteilung
C5: SCHRITT 04 / 12 · KAUFPREISAUFTEILUNG | I5: ‹ Leitfaden
C6: Kaufpreisaufteilung | H6: =Obj_Name -> Beispiel: 3-Zimmer-Eigentumswohnung
C7: Nur der Gebäudeanteil ist abschreibbar – die Aufteilung zwischen Grund und Boden und Gebäude. | H7: =Obj_Adresse&IFERROR(IF(Erstellt_fuer="",""," · Erstellt für "&Erstellt_fuer),"") -> Musterstraße 1, 88250 Weingarten · Erstellt für Max Mustermann
C10: Eingaben | H10: Ergebnis dieses Schritts | I10: beim Kauf
C11: POSITION | D11: EINGABE | E11: EINHEIT | F11: HINWEIS | H11: Kaufpreis ohne Inventar/Rücklage | I11: =KP_Immobilie -> 274000
C12: Methode der Kaufpreisaufteilung | D12: Bodenrichtwert × Grundstücks-/Miteigentumsanteil | F12: Standard: BMF-Arbeitshilfe · Gutachten möglich | H12: Bodenwert (nicht abschreibbar) | I12: =Bodenwert -> 54000
C13: Bodenrichtwert | D13: 450 | E13: je m² | F13: lt. Gutachterausschuss / BORIS (Methode 1) | H13: Gebäudeanteil am Kaufpreis | I13: =Gebaeudeanteil_Pct -> 0.80291971
C14: Bodenanteil in % des Kaufpreises | D14: 0.2 | F14: nur Methode „Bodenanteil in %“ | H14: AK Grund und Boden (inkl. NK) | I14: =AK_Boden -> 59956.653
C15: Gebäudewert (Gutachten / Vertrag) | F15: nur Methode „Gebäudewert“ (ohne Inventar) | H15: = AfA-Basis Gebäude (inkl. NK) | I15: =AK_Gebaeude -> 244267.85
H16: nachrichtlich: bewegliche Gegenstände | I16: =KP_bewegl -> 8000
C17: AUFTEILUNG DES KAUFPREISES | F17: inkl. Inventar und Rücklage · Anteile in %
H18: Gebäudeanteil und AfA
H19: Nur der Gebäudeanteil wird abgeschrieben – ein hoher Bodenanteil senkt die jährliche AfA. Das Finanzamt rechnet mit der BMF-Arbeitshilfe; eine im Kaufvertrag vereinbarte Aufteilung ist maßgeblich, wenn sie den realen Wertverhältnissen entspricht (BFH IX R 26/19). Ein Gutachten ersetzt die Arbeitshilfe.
H21: AfA-BASIS GEBÄUDE
H22: =AK_Gebaeude -> 244267.85
H23: ="Reguläre Gebäude-AfA Jahr 1: "&FIXED(INDEX(Steuern!$D$49:$AQ$49,1),0)&" €" -> Reguläre Gebäude-AfA Jahr 1: 4,885 €
H25: ALS NÄCHSTES | I25: Schritt 05 / 12
H26: Maßnahmen & Reserve · Renovierung, Sonderumlagen und Liquiditätsreserve – inklusive Prüfung der 15 %-Grenze.
C29: ‹ Zurück: Kaufnebenkosten | E29: Übersicht: Leitfaden | H29: Weiter: Maßnahmen & Reserve ›
C31: Keine Gewähr für die Richtigkeit der Angaben · ersetzt keine Rechts-, Steuer- oder Finanzberatung · Rechtsstand September 2026
C32: MM Holding GmbH · Kornhausgasse 4 · 88250 Weingarten · Amtsgericht Ulm HRB 750729

Sheet S05 Maßnahmen & Reserve
C5: SCHRITT 05 / 12 · MASSNAHMEN & RESERVE | I5: ‹ Leitfaden
C6: Maßnahmen & Reserve | H6: =Obj_Name -> Beispiel: 3-Zimmer-Eigentumswohnung
C7: Renovierung, Sonderumlagen und Liquiditätsreserve – inklusive Prüfung der 15 %-Grenze. | H7: =Obj_Adresse&IFERROR(IF(Erstellt_fuer="",""," · Erstellt für "&Erstellt_fuer),"") -> Musterstraße 1, 88250 Weingarten · Erstellt für Max Mustermann
C10: Eingaben | H10: Ergebnis dieses Schritts | I10: Jahre 1–3
C11: POSITION | D11: EINGABE | E11: EINHEIT | F11: HINWEIS | H11: Maßnahmen Jahre 1–3 (netto) | I11: =Reno_Netto -> 10084.034
C12: Renovierung Jahr 1 (brutto) | D12: 12000 | F12: Teil des anfänglichen Kapitalbedarfs | H12: 15 %-Grenze (Gebäude-AK × 15 %) | I12: =Grenze_15 -> 36640.177
C13: Renovierung Jahr 2 (brutto) | D13: 0 | F13: aus laufendem Cashflow / Eigenkapital | H13: Steuerliche Behandlung | I13: =IF(HK_Flag=1,"Aktiviert (AfA)",IF(Verteilung_eff>1,"Verteilt (§ 82b)","Sofortabzug")) -> Sofortabzug
C14: Renovierung Jahr 3 (brutto) | D14: 0 | F14: Jahre 1–3 zählen für die 15 %-Grenze | H14: Maßnahmen + Sonderumlage Jahr 1 | I14: =Investition_J1 -> 12000
C15: Sonderumlagen der WEG (Jahr 1) | D15: 0 | F15: Erhaltungsaufwand · zählt zur 15 %-Grenze | H15: = Gesamtinvestition | I15: =Gesamtinvestition -> 328974.5
C16: Steuerliche Behandlung | D16: Automatisch – 15 %-Grenze prüfen (§ 6 Abs. 1 Nr. 1a EStG) | F16: § 6 Abs. 1 Nr. 1a EStG · über 15 % → AfA | H16: = Eigenkapitalbedarf inkl. Reserve | I16: =EK_Bedarf_gesamt -> 83974.5
C17: Verteilung Erhaltungsaufwand | D17: 1 | F17: § 82b EStDV · 1 = sofort, 2–5 = verteilt (Privat)
C18: Wertsteigernder Anteil | D18: 1 | F18: Anteil der Maßnahmen, der den Objektwert erhöht | H18: Die 15 %-Grenze
C19: Einmalige Liquiditätsreserve | D19: 5000 | F19: z. B. Mieterwechsel · erhöht nur das Eigenkapital | H19: =IF(Reno_Netto>Grenze_15,"Achtung: Die Maßnahmen (netto "&FIXED(Reno_Netto,0)&" €) übersteigen 15 % der Gebäude-Anschaffungskosten ("&FIXED(Grenze_15,0)&" €). Damit liegen anschaffungsnahe Herstellungskosten vor (§ 6 Abs. 1 Nr. 1a EStG): kein Sofortabzug, sondern AfA – auch wenn einzelne Maßnahmen für sich Erhaltungsaufwand wären.","Die Maßnahmen (netto "&FIXED(Reno_Netto,0)&" €) bleiben unter der 15 %-Grenze von "&FIXED(Grenze_15,0)&" € – Sofortabzug als Erhaltungsaufwand ist möglich. Bei hoher Progression kann eine Verteilung auf 2 bis 5 Jahre (§ 82b EStDV) sinnvoll sein. Weitere Instandsetzungen in den ersten drei Jahren zählen mit.") -> Die Maßnahmen (netto 10,084 €) bleiben unter der 15 %-Grenze von 36,640 € – Sofortabzug als Erhaltungsaufwand ist möglich. Bei hoher Progression kann eine Verteilung auf 2 bis 5 Jahre (§ 82b EStDV) sinnvoll sein. Weitere Instandsetzungen in den ersten drei Jahren zählen mit.
C21: ZUSAMMENSETZUNG DER GESAMTINVESTITION | F21: Anteile in %
H23: EIGENKAPITALBEDARF INKL. RESERVE
H24: =EK_Bedarf_gesamt -> 83974.5
H25: =IFERROR("Anteil an der Gesamtinvestition "&FIXED(EK_Bedarf_gesamt/Gesamtinvestition*100,1)&" %","") -> Anteil an der Gesamtinvestition 25.5 %
H27: ALS NÄCHSTES | I27: Schritt 06 / 12
H28: Bewirtschaftung · Hausgeld, Verwaltung, Rücklagen und Mietausfall – was von der Miete monatlich übrig bleibt.
C31: ‹ Zurück: Kaufpreisaufteilung | E31: Übersicht: Leitfaden | H31: Weiter: Bewirtschaftung ›
C33: Keine Gewähr für die Richtigkeit der Angaben · ersetzt keine Rechts-, Steuer- oder Finanzberatung · Rechtsstand September 2026
C34: MM Holding GmbH · Kornhausgasse 4 · 88250 Weingarten · Amtsgericht Ulm HRB 750729

Sheet S06 Bewirtschaftung
C5: SCHRITT 06 / 12 · BEWIRTSCHAFTUNG | I5: ‹ Leitfaden
C6: Bewirtschaftung | H6: =Obj_Name -> Beispiel: 3-Zimmer-Eigentumswohnung
C7: Hausgeld, Verwaltung, Rücklagen und Mietausfall – was von der Miete monatlich übrig bleibt. | H7: =Obj_Adresse&IFERROR(IF(Erstellt_fuer="",""," · Erstellt für "&Erstellt_fuer),"") -> Musterstraße 1, 88250 Weingarten · Erstellt für Max Mustermann
C10: Eingaben | H10: Ergebnis dieses Schritts | I10: Jahr 1 · pro Monat
C11: POSITION | D11: EINGABE | E11: EINHEIT | F11: HINWEIS | H11: Nettokaltmiete Ist (nach Ausfall) | I11: =INDEX(Projektion!$D$15:$AQ$15,1)/12 -> 921.5
C12: Hausgeld gesamt (WEG) | D12: 310 | E12: pro Monat | F12: lt. Wirtschaftsplan | H12: – Bewirtschaftung inkl. Rücklagen | I12: =INDEX(Projektion!$D$26:$AQ$26,1)/12 -> 207.5
C13: davon nicht umlagefähig | D13: 95 | E13: pro Monat | F13: Verwaltung WEG, Rücklage, Sonstiges – trägt der Eigentümer | H13: in % der Nettokaltmiete | I13: =IF(INDEX(Projektion!$D$15:$AQ$15,1)>0,INDEX(Projektion!$D$26:$AQ$26,1)/INDEX(Projektion!$D$15:$AQ$15,1),0) -> 0.22517634
C14: davon Erhaltungsrücklage | D14: 60 | E14: pro Monat | F14: Teil von „nicht umlagefähig“ · Abzug erst bei Verausgabung | H14: = Einnahmenüberschuss (NOI) | I14: =INDEX(Projektion!$D$29:$AQ$29,1)/12 -> 714
C15: Miet-/SE-Verwaltung | D15: 25 | E15: pro Monat | F15: Werbungskosten | H15: = Nettomietrendite | I15: =IF(Gesamtinvestition>0,INDEX(Projektion!$D$29:$AQ$29,1)/Gesamtinvestition,0) -> 0.026044572
C16: Eigene Instandhaltungsrücklage | D16: 10 | E16: je m² p. a. | F16: kalkulatorisch, Faustwert 8–15 €/m² · nicht steuerwirksam
C17: Mietausfallwagnis | D17: 0.03 | E17: der Miete | F17: kalkulatorisch 2–4 % | H17: Nettomietrendite | I17: =IF(AND(ISNUMBER(S06_NMR),S06_NMR<Ampel_NMR_gelb),"● kritisch"&" · "&FIXED(S06_NMR*100,1)&" %",IF(AND(ISNUMBER(S06_NMR),S06_NMR<Ampel_NMR_gruen),"● prüfen"&" · "&FIXED(S06_NMR*100,1)&" %",IF(ISNUMBER(S06_NMR),"● erfüllt"&" · "&FIXED(S06_NMR*100,1)&" %",""))) -> ● prüfen · 2.6 %
C18: Leerstand zu Beginn | D18: 0 | F18: Renovierung / Neuvermietung · mindert die Miete Jahr 1 | H18: =IF(S06_NMR<Ampel_NMR_gruen,"Die Nettomietrendite liegt unter dem Ziel von "&FIXED(Ampel_NMR_gruen*100,1)&" %.","Die Nettomietrendite erreicht das Ziel von "&FIXED(Ampel_NMR_gruen*100,1)&" %.")&" "&"Nicht umlagefähige Kosten trägt der Eigentümer. Zuführungen zur WEG-Erhaltungsrücklage und die eigene Instandhaltungsrücklage sind Liquiditätsabflüsse, steuerlich aber erst bei tatsächlicher Verausgab"&"ung abziehbar. Mietausfallwagnis und Leerstand mindern die Ist-Miete." -> Die Nettomietrendite liegt unter dem Ziel von 3.5 %. Nicht umlagefähige Kosten trägt der Eigentümer. Zuführungen zur WEG-Erhaltungsrücklage und die eigene Instandhaltungsrücklage sind Liquiditätsabflüsse, steuerlich aber erst bei tatsächlicher Verausgabung abziehbar. Mietausfallwagnis und Leerstand mindern die Ist-Miete.
C19: Sonstige Werbungskosten | D19: 300 | E19: pro Jahr | F19: Steuerberatung, Kontoführung, Fahrten
C21: BEWIRTSCHAFTUNGSKOSTEN JAHR 1 | F21: € p. a. · Anteile
H22: EINNAHMENÜBERSCHUSS (NOI) / MONAT
H23: =INDEX(Projektion!$D$29:$AQ$29,1)/12 -> 714
H24: ="Jahr 1 · "&FIXED(INDEX(Projektion!$D$29:$AQ$29,1),0)&" € p. a." -> Jahr 1 · 8,568 € p. a.
H26: ALS NÄCHSTES | I26: Schritt 07 / 12
H27: Finanzierung · Darlehen, Zins, Tilgung und Zinsbindung – Rate, Eigenkapital und Restschuld nach der Zinsbindung.
C30: ‹ Zurück: Maßnahmen & Reserve | E30: Übersicht: Leitfaden | H30: Weiter: Finanzierung ›
C32: Keine Gewähr für die Richtigkeit der Angaben · ersetzt keine Rechts-, Steuer- oder Finanzberatung · Rechtsstand September 2026
C33: MM Holding GmbH · Kornhausgasse 4 · 88250 Weingarten · Amtsgericht Ulm HRB 750729
C60: DIAGRAMMDATEN (AUTOMATISCH)
C61: Hausgeld n. umlagefähig (ohne Rücklage) | D61: =INDEX(Projektion!$D$20:$AQ$20,1) -> 420
C62: Zuführung Erhaltungsrücklage | D62: =INDEX(Projektion!$D$21:$AQ$21,1) -> 720
C63: Verwaltung | D63: =INDEX(Projektion!$D$22:$AQ$22,1) -> 300
C64: Eigene Instandhaltungsrücklage | D64: =INDEX(Projektion!$D$24:$AQ$24,1) -> 750
C65: Mietausfall | D65: =INDEX(Projektion!$D$14:$AQ$14,1) -> 342
C66: Sonstige Werbungskosten | D66: =INDEX(Projektion!$D$23:$AQ$23,1) -> 300

Sheet S07 Finanzierung
C5: SCHRITT 07 / 12 · FINANZIERUNG | I5: ‹ Leitfaden
C6: Finanzierung | H6: =Obj_Name -> Beispiel: 3-Zimmer-Eigentumswohnung
C7: Darlehen, Zins, Tilgung und Zinsbindung – Rate, Eigenkapital und Restschuld nach der Zinsbindung. | H7: =Obj_Adresse&IFERROR(IF(Erstellt_fuer="",""," · Erstellt für "&Erstellt_fuer),"") -> Musterstraße 1, 88250 Weingarten · Erstellt für Max Mustermann
C10: Eingaben | H10: Ergebnis dieses Schritts | I10: Kauf · Rate Jahr 1
C11: POSITION | D11: EINGABE | E11: EINHEIT | F11: HINWEIS | H11: Darlehen gesamt (inkl. Darlehen II) | I11: =Darlehen_Summe -> 250000
C12: Darlehen I – Betrag | D12: 250000 | F12: Bankdarlehen (Annuität) | H12: Finanzierungsnebenkosten | I12: =FinNK_Summe -> 1750
C13: Darlehen I – Sollzins p. a. | D13: 0.036 | H13: = Eigenkapital (ohne Reserve) | I13: =Eigenkapital -> 78974.5
C14: Darlehen I – anfängliche Tilgung p. a. | D14: 0.02 | F14: Annuität = (Zins + Tilgung) × Darlehen, konstant | H14: Eigenkapitalquote | I14: =EK_Quote -> 0.24006268
C15: Darlehen I – Zinsbindung | D15: 10 | H15: Beleihungsauslauf | I15: =Beleihung -> 0.87719298
C16: Darlehen I – Anschlusszins | D16: 0.045 | F16: nach der Zinsbindung · Annahme, die Annuität bleibt | H16: Restschuld nach Zinsbindung | I16: =Restschuld_ZB_I -> 191071.23
C17: Darlehen I – Sondertilgung p. a. | D17: 0 | E17: pro Jahr | H17: Volltilgung | I17: =Volltilgung_Txt -> Jahr 32 (2057)
C18: Darlehen I – tilgungsfreie Jahre | D18: 0 | H18: = Rate an die Bank / Monat | I18: =Kapitaldienst_Monat_J1 -> 1166.6667
C19: Grundschuldbestellung | D19: 0.005 | F19: Notar + Grundbuch, ca. 0,4–0,6 % des Darlehens
C20: Bearbeitungs-/Vermittlungsgebühr | D20: 500 | F20: Bank, Wertermittlung · sofort abziehbar | H20: Kapitaldienstdeckung (DSCR) | I20: =IF(AND(ISNUMBER(DSCR_J1),DSCR_J1<Ampel_DSCR_gelb),"● kritisch"&" · "&FIXED(DSCR_J1,2)&"×",IF(AND(ISNUMBER(DSCR_J1),DSCR_J1<Ampel_DSCR_gruen),"● prüfen"&" · "&FIXED(DSCR_J1,2)&"×",IF(ISNUMBER(DSCR_J1),"● erfüllt"&" · "&FIXED(DSCR_J1,2)&"×",""))) -> ● kritisch · 0.61×
C21: Disagio Darlehen I | D21: 0 | F21: bis 5 % bei ≥ 5 Jahren Zinsbindung sofort abziehbar | H21: =IF(NOT(ISNUMBER(DSCR_J1)),"Ohne Darlehen entfällt die Kapitaldienstdeckung.",IF(DSCR_J1>=Ampel_DSCR_gruen,"Der Einnahmenüberschuss deckt die Rate an die Bank mit Reserve – Banken erwarten mindestens "&FIXED(Ampel_DSCR_gruen,2)&"×.",IF(DSCR_J1>=Ampel_DSCR_gelb,"Knapp: Banken erwarten meist mindestens "&FIXED(Ampel_DSCR_gruen,2)&"× – mehr Eigenkapital oder Sicherheiten einplanen.","Der Einnahmenüberschuss deckt nur "&FIXED(DSCR_J1*100,0)&" % der Rate. Banken erwarten mindestens "&FIXED(Ampel_DSCR_gruen,2)&"× – den Rest tragen Sie aus Ihrem Einkommen."))) -> Der Einnahmenüberschuss deckt nur 61 % der Rate. Banken erwarten mindestens 1.20× – den Rest tragen Sie aus Ihrem Einkommen.
C23: Hinweis Ein zweites Darlehen (z. B. KfW) erfassen Sie auf dem Blatt „Eingaben“. | F23: Darlehen II erfassen ›
H24: Zinsänderungsrisiko
C25: RESTSCHULD AM JAHRESENDE | F25: Jahre 1–35 · T€ · Jahresende | H25: ="Nach "&Zinsbindung_I&" Jahren stehen noch "&FIXED(Restschuld_ZB_I,0)&" € Restschuld. Jeder Prozentpunkt mehr Anschlusszins kostet "&FIXED(Restschuld_ZB_I*0.01,0)&" € pro Jahr ("&FIXED(Restschuld_ZB_I*0.01/12,0)&" € pro Monat). Angenommen sind "&FIXED(Anschlusszins_I*100,2)&" % ab Jahr "&(Zinsbindung_I+1)&". Sondertilgungen und eine höhere Anfangstilgung reduzieren dieses Risiko." -> Nach 10 Jahren stehen noch 191,071 € Restschuld. Jeder Prozentpunkt mehr Anschlusszins kostet 1,911 € pro Jahr (159 € pro Monat). Angenommen sind 4.50 % ab Jahr 11. Sondertilgungen und eine höhere Anfangstilgung reduzieren dieses Risiko.
H28: FINANZIERUNGSSTRUKTUR | I28: Anteile in %
C41: ‹ Zurück: Bewirtschaftung | E41: Übersicht: Leitfaden | H41: Weiter: Zwischenergebnis ›
C43: Keine Gewähr für die Richtigkeit der Angaben · ersetzt keine Rechts-, Steuer- oder Finanzberatung · Rechtsstand September 2026
C44: MM Holding GmbH · Kornhausgasse 4 · 88250 Weingarten · Amtsgericht Ulm HRB 750729

Sheet S08 Zwischenergebnis
C5: SCHRITT 08 / 12 · ZWISCHENERGEBNIS | I5: ‹ Leitfaden
C6: Zwischenergebnis | H6: =Obj_Name -> Beispiel: 3-Zimmer-Eigentumswohnung
C7: Cashflow vor Steuern: Miete abzüglich Bewirtschaftung, Zinsen und Tilgung. | H7: =Obj_Adresse&IFERROR(IF(Erstellt_fuer="",""," · Erstellt für "&Erstellt_fuer),"") -> Musterstraße 1, 88250 Weingarten · Erstellt für Max Mustermann
C10: Cashflow vor Steuern – Jahr 1 | H10: Cashflow vor Steuern | I10: =IF(CF_vSt_J1<0,"● kritisch"&" · "&IF(CF_vSt_J1<0,"−","")&FIXED(ABS(CF_vSt_J1/12),0)&" €",IF(ISNUMBER(CF_vSt_J1),"● erfüllt"&" · "&IF(CF_vSt_J1<0,"−","")&FIXED(ABS(CF_vSt_J1/12),0)&" €","")) -> ● kritisch · −453 €
C11: NETTOKALTMIETE IST / MONAT | E11: EINNAHMENÜBERSCHUSS (NOI) / MONAT | H11: =IF(CF_vSt_J1>=0,"Die Miete deckt Bewirtschaftung, Zinsen und Tilgung: Es bleiben "&FIXED(CF_vSt_J1/12,0)&" € pro Monat vor Steuern für Rücklagen oder Sondertilgungen.","Es fehlen "&FIXED(-CF_vSt_J1/12,0)&" € pro Monat, die aus anderen Einkünften zugeschossen werden. Ob sich das Objekt trotzdem lohnt, zeigen Steuereffekt (Schritte 9–10) und Wertentwicklung (Schritt 11).") -> Es fehlen 453 € pro Monat, die aus anderen Einkünften zugeschossen werden. Ob sich das Objekt trotzdem lohnt, zeigen Steuereffekt (Schritte 9–10) und Wertentwicklung (Schritt 11).
C12: =INDEX(Projektion!$D$15:$AQ$15,1)/12 -> 921.5 | E12: =INDEX(Projektion!$D$29:$AQ$29,1)/12 -> 714
C13: nach Mietausfall und Leerstand | E13: Miete abzüglich Bewirtschaftung
C14: RATE AN DIE BANK / MONAT | E14: CASHFLOW V. ST. / MONAT (JAHR 1) | H14: Kapitaldienstdeckung (DSCR) | I14: =IF(AND(ISNUMBER(DSCR_J1),DSCR_J1<Ampel_DSCR_gelb),"● kritisch"&" · "&FIXED(DSCR_J1,2)&"×",IF(AND(ISNUMBER(DSCR_J1),DSCR_J1<Ampel_DSCR_gruen),"● prüfen"&" · "&FIXED(DSCR_J1,2)&"×",IF(ISNUMBER(DSCR_J1),"● erfüllt"&" · "&FIXED(DSCR_J1,2)&"×",""))) -> ● kritisch · 0.61×
C15: =Kapitaldienst_Monat_J1 -> 1166.6667 | E15: =CF_vSt_J1/12 -> -452.66667 | H15: ="Banken erwarten meist eine Kapitaldienstdeckung von mindestens "&FIXED(Ampel_DSCR_gruen,2)&"× (Einnahmenüberschuss ÷ Rate). Darunter trägt der Investor einen Teil der Rate aus seinem Einkommen." -> Banken erwarten meist eine Kapitaldienstdeckung von mindestens 1.20× (Einnahmenüberschuss ÷ Rate). Darunter trägt der Investor einen Teil der Rate aus seinem Einkommen.
C16: Zinsen und Tilgung · Jahr 1 | E16: Ziel ≥ 0 € · nach Rate, vor Steuern | F16: =IF($E$15<0,"● kritisch",IF(ISNUMBER($E$15),"● erfüllt","")) -> ● kritisch
C17: HERLEITUNG PRO MONAT | D17: Jahr 1 | E17: EINNAHMEN VS. AUSGABEN | F17: € / Monat · vor Steuern | H17: STELLSCHRAUBEN | I17: Cashflow verbessern
C18: Nettokaltmiete Ist | D18: =INDEX(Projektion!$D$15:$AQ$15,1)/12 -> 921.5 | H18: Kaufpreis & Miete – Miete und Kaufpreis ›
C19: – Bewirtschaftung inkl. Rücklagen | D19: =INDEX(Projektion!$D$26:$AQ$26,1)/12 -> 207.5 | H19: Bewirtschaftung – nicht umlagefähige Kosten ›
C20: – Zinsen | D20: =INDEX(Projektion!$D$30:$AQ$30,1)/12 -> 750 | H20: Finanzierung – Eigenkapital, Zins und Tilgung ›
C21: – Tilgung | D21: =INDEX(Projektion!$D$31:$AQ$31,1)/12 -> 416.66667 | H21: Steuern – Rechtsform und Steuersatz ›
C22: = Cashflow vor Steuern / Monat | D22: =INDEX(Projektion!$D$33:$AQ$33,1)/12 -> -452.66667 | H22: Sensitivität – Break-even-Miete und Zinsänderung ›
C23: Kapitaldienstdeckung (DSCR) | D23: =DSCR_J1 -> 0.612 | H23: Cockpit – alle Kennzahlen im Detail ›
C26: ‹ Zurück: Finanzierung | E26: Übersicht: Leitfaden | H26: Weiter: Steuern ›
C28: Keine Gewähr für die Richtigkeit der Angaben · ersetzt keine Rechts-, Steuer- oder Finanzberatung · Rechtsstand September 2026
C29: MM Holding GmbH · Kornhausgasse 4 · 88250 Weingarten · Amtsgericht Ulm HRB 750729

Sheet S09 Steuern
C5: SCHRITT 09 / 12 · STEUERN | I5: ‹ Leitfaden
C6: Steuern | H6: =Obj_Name -> Beispiel: 3-Zimmer-Eigentumswohnung
C7: Rechtsform (Privat oder GmbH), Einkommen, Soli und Kirchensteuer – der angewendete Steuersatz. | H7: =Obj_Adresse&IFERROR(IF(Erstellt_fuer="",""," · Erstellt für "&Erstellt_fuer),"") -> Musterstraße 1, 88250 Weingarten · Erstellt für Max Mustermann
C10: Eingaben | H10: Ergebnis dieses Schritts | I10: Jahr 1
C11: POSITION | D11: EINGABE | E11: EINHEIT | F11: HINWEIS | H11: Grenzsteuersatz lt. Tarif 2026 | I11: =Grenzsteuersatz_Tarif -> 0.42
C12: Rechtsform | D12: =CHOOSE(Rechtsform_Idx,"Privatperson","vv-GmbH","GmbH / Holding") -> Privatperson | F12: Kauf als auf der Startseite ändern › | H12: Grenzbelastung inkl. Soli / KiSt | I12: =Steuersatz_Privat -> 0.462588
C13: Veranlagung | D13: Einzelveranlagung (Grundtarif) | F13: nur Privatperson | H13: Steuersatz GmbH Jahr 1 | I13: =Steuersatz_GmbH_J1 -> 0.15825
C14: Einkommen ohne dieses Objekt (zvE) | D14: 75000 | E14: pro Jahr | F14: nur Privatperson · Basis für den Grenzsteuersatz | H14: = Angewendeter Steuersatz Jahr 1 | I14: =Steuersatz_J1 -> 0.462588
C15: Grenzsteuersatz manuell | F15: nur Privat · optional, leer = nach Tarif 2026 | H15: Steuerliches Ergebnis Jahr 1 | I15: =Ergebnis_J1 -> -18397.357
C16: Solidaritätszuschlag | D16: Ja | F16: nur Privat · „Nein“ bei ESt unter der Freigrenze | H16: = Steuerwirkung Jahr 1 | I16: =INDEX(Steuern!$D$73:$AQ$73,1) -> -8510.3965
C17: Kirchensteuer | D17: 8 % (Baden-Württemberg, Bayern) | F17: nur Privat · Sonderausgabenabzug berücksichtigt
C18: Gewerbesteuer-Hebesatz | D18: 4 | F18: nur GmbH ohne erweiterte Kürzung · z. B. 400 % | H18: Besteuerung nach Rechtsform
H19: =IF(Rechtsform_Idx=1,"Privatperson: Das steuerliche Ergebnis (Miete abzüglich Werbungskosten, Zinsen und AfA) wird mit dem Grenzsteuersatz belastet – ein Verlust im Jahr 1 mindert die übrige Einkommensteuer (Erstattung). Nach zehn Jahren ist der Verkauf steuerfrei (§ 23 EStG).",IF(Rechtsform_Idx=2,"Vermögensverwaltende GmbH: Körperschaftsteuer 15 % (ab 2028 jährlich sinkend auf 10 % ab 2032) zuzüglich Soli; mit erweiterter Kürzung keine Gewerbesteuer auf Mieterträge. Verluste werden vorgetragen, der Verkauf ist immer steuerpflichtig. Ausschüttungen an Gesellschafter werden zusätzlich besteuert.","Gewerbliche GmbH: Körperschaftsteuer zuzüglich Soli und Gewerbesteuer ("&FIXED(GewSt_Satz*100,2)&" % bei Hebesatz "&FIXED(Hebesatz*100,0)&" %). Verluste werden vorgetragen; der Verkauf ist immer steuerpflichtig.")) -> Privatperson: Das steuerliche Ergebnis (Miete abzüglich Werbungskosten, Zinsen und AfA) wird mit dem Grenzsteuersatz belastet – ein Verlust im Jahr 1 mindert die übrige Einkommensteuer (Erstattung). Nach zehn Jahren ist der Verkauf steuerfrei (§ 23 EStG).
C20: STEUERLICHES ERGEBNIS UND STEUER | F20: Jahre 1–20 · T€ · Steuer: + Zahlung / − Erstattung
H23: STEUERWIRKUNG / MONAT (JAHR 1)
H24: =Steuer_J1/12 -> -709.19971
H25: =IF(Steuer_J1<0,"Erstattung","Zahlung")&" · Cash-Sicht wie Schritt 12" -> Erstattung · Cash-Sicht wie Schritt 12
H27: ALS NÄCHSTES | I27: Schritt 10 / 12
H28: Abschreibung · AfA-Methode, Sonder-AfA § 7b und erhöhte Absetzungen § 7h/7i – die steuerliche Hebelwirkung.
C31: ‹ Zurück: Zwischenergebnis | E31: Übersicht: Leitfaden | H31: Weiter: Abschreibung ›
C33: Keine Gewähr für die Richtigkeit der Angaben · ersetzt keine Rechts-, Steuer- oder Finanzberatung · Rechtsstand September 2026
C34: MM Holding GmbH · Kornhausgasse 4 · 88250 Weingarten · Amtsgericht Ulm HRB 750729

Sheet S10 Abschreibung
C5: SCHRITT 10 / 12 · ABSCHREIBUNG | I5: ‹ Leitfaden
C6: Abschreibung | H6: =Obj_Name -> Beispiel: 3-Zimmer-Eigentumswohnung
C7: AfA-Methode, Sonder-AfA § 7b und erhöhte Absetzungen § 7h/7i – die steuerliche Hebelwirkung. | H7: =Obj_Adresse&IFERROR(IF(Erstellt_fuer="",""," · Erstellt für "&Erstellt_fuer),"") -> Musterstraße 1, 88250 Weingarten · Erstellt für Max Mustermann
C10: Eingaben | H10: Ergebnis dieses Schritts | I10: Jahr 1
C11: POSITION | D11: EINGABE | E11: EINHEIT | F11: HINWEIS | H11: Angewendete AfA-Methode | I11: =IF(Methode_eff=5,"Degressiv 5 %",IF(Methode_eff=6,"Gutachten (RND)","Linear "&FIXED(CHOOSE(Methode_eff,AfA_Satz_auto,0.02,0.025,0.03)*100,1)&" %")) -> Linear 2.0 %
C12: AfA-Methode Gebäude | D12: Automatisch nach Baujahr (§ 7 Abs. 4 EStG) | F12: degressiv nur bei Baubeginn 10/2023 – 09/2029 | H12: Reguläre Gebäude-AfA | I12: =INDEX(Steuern!$D$49:$AQ$49,1) -> 4885.3569
C13: Restnutzungsdauer lt. Gutachten | D13: 0 | F13: nur Methode Gutachten · kürzere Restnutzungsdauer | H13: + Sonder-AfA § 7b | I13: =INDEX(Steuern!$D$50:$AQ$50,1) -> 0
C14: Degressiv: Wechsel zur linearen AfA | D14: Ja | F14: nur degressive AfA · Wechsel, sobald vorteilhaft | H14: + Erhöhte Absetzungen § 7h/7i | I14: =INDEX(Steuern!$D$54:$AQ$54,1) -> 0
C15: Sonder-AfA § 7b (Neubau) | D15: Nein | F15: 5 % p. a. für 4 Jahre · EH 40 + QNG, Baukostengrenze | H15: + AfA bewegliche Gegenstände | I15: =INDEX(Steuern!$D$55:$AQ$55,1) -> 800
C16: Erhöhte AfA § 7h / § 7i EStG | D16: Nein | F16: Sanierungsgebiet / Denkmal: 9 % (J. 1–8), 7 % (J. 9–12) | H16: = Abschreibungen gesamt Jahr 1 | I16: =INDEX(Steuern!$D$56:$AQ$56,1) -> 5685.3569
C17: Begünstigte Kosten § 7h / 7i | D17: 0 | F17: im Kaufpreis enthalten · lt. Bescheinigung | H17: Steuereffekt ggü. Standard-AfA (10 J.) | I17: =Steuereffekt_10J -> 0
C19: ABSCHREIBUNGEN NACH KOMPONENTEN | F19: Jahre 1–20 · T€ p. a. | H19: Wahl der Abschreibung
H20: =IF(AND(AfA_Idx=5,Methode_eff<>5),"Die degressive AfA ist für dieses Objekt nicht anwendbar (Fertigstellung vor 2023 oder Gewerbeeinheit) – es wird linear nach Baujahr abgeschrieben.",IF(AND(SonderAfA_7b="Ja",SonderAfA_aktiv=0),"Die Sonder-AfA § 7b greift nicht: Fertigstellung vor 2023, Gewerbeeinheit oder Anschaffungskosten über "&FIXED(Grenze_7b_Baukosten,0)&" €/m² (aktuell "&FIXED(Baukosten_qm,0)&" €/m²).",IF(SonderAfA_aktiv=1,"Sonder-AfA § 7b aktiv: 5 % p. a. auf "&FIXED(SonderAfA_BMG,0)&" € in den Jahren 1–4 zusätzlich zur regulären AfA; ab Jahr 5 Restwert-AfA. Voraussetzung: Effizienzhaus 40 mit QNG-Siegel.","Eine höhere AfA in den ersten Jahren ist ein Liquiditäts- und Zinsvorteil (Steuerstundung): Bei einem Verkauf innerhalb der Zehnjahresfrist (Privat) oder in der GmbH erhöht die kumulierte AfA den steuerpflichtigen Veräußerungsgewinn. Den vollständigen Variantenvergleich zeigt das Blatt „AfA-Vergleich“."))) -> Eine höhere AfA in den ersten Jahren ist ein Liquiditäts- und Zinsvorteil (Steuerstundung): Bei einem Verkauf innerhalb der Zehnjahresfrist (Privat) oder in der GmbH erhöht die kumulierte AfA den steuerpflichtigen Veräußerungsgewinn. Den vollständigen Variantenvergleich zeigt das Blatt „AfA-Vergleich“.
H22: ABSCHREIBUNGEN / MONAT (JAHR 1)
H23: =INDEX(Steuern!$D$56:$AQ$56,1)/12 -> 473.77974
H24: ="Jahr 1 gesamt: "&FIXED(INDEX(Steuern!$D$56:$AQ$56,1),0)&" € p. a." -> Jahr 1 gesamt: 5,685 € p. a.
H26: ALS NÄCHSTES | I26: Schritt 11 / 12
H27: Prognose & Exit · Miet-, Kosten- und Wertsteigerung, Haltedauer und Verkauf – inklusive 10-Jahres-Frist.
C30: ‹ Zurück: Steuern | E30: Übersicht: Leitfaden | H30: Weiter: Prognose & Exit ›
C32: Keine Gewähr für die Richtigkeit der Angaben · ersetzt keine Rechts-, Steuer- oder Finanzberatung · Rechtsstand September 2026
C33: MM Holding GmbH · Kornhausgasse 4 · 88250 Weingarten · Amtsgericht Ulm HRB 750729

Sheet S11 Prognose & Exit
C5: SCHRITT 11 / 12 · PROGNOSE & EXIT | I5: ‹ Leitfaden
C6: Prognose & Exit | H6: =Obj_Name -> Beispiel: 3-Zimmer-Eigentumswohnung
C7: Miet-, Kosten- und Wertsteigerung, Haltedauer und Verkauf – inklusive 10-Jahres-Frist. | H7: =Obj_Adresse&IFERROR(IF(Erstellt_fuer="",""," · Erstellt für "&Erstellt_fuer),"") -> Musterstraße 1, 88250 Weingarten · Erstellt für Max Mustermann
C10: Eingaben | H10: Ergebnis dieses Schritts | I10: Verkauf
C11: POSITION | D11: EINGABE | E11: EINHEIT | F11: HINWEIS | H11: Verkaufspreis bei Exit | I11: =Exit_VP -> 376667.81
C12: Mietsteigerung p. a. | D12: 0.02 | F12: Prognose · Mietpreisbremse und Kappungsgrenze | H12: Veräußerungsgewinn (steuerlich) | I12: =Exit_Gewinn -> 120534.24
C13: Kostensteigerung p. a. | D13: 0.02 | F13: Prognose | H13: Verkauf steuerpflichtig? | I13: =IF(Exit_steuerpflichtig=1,"Ja","Nein") -> Nein
C14: Wertsteigerung p. a. | D14: 0.02 | F14: Prognose; konservativ 0–2 % | H14: Steuer auf den Veräußerungsgewinn | I14: =Exit_Steuer -> 0
C15: Geplante Haltedauer | D15: 12 | F15: Privat: Verkauf nach über 10 Jahren steuerfrei | H15: = Nettoerlös nach Steuer und Ablösung | I15: =Exit_Netto -> 189109.9
C16: Verkaufskosten | D16: 0.02 | F16: vom Verkaufspreis · Makler, Notar, Löschung | H16: Gesamtertrag nach Steuern | I16: =Gesamtertrag -> 77296.866
C17: Verkaufspreis manuell | F17: optional · leer = Wertentwicklung lt. Prognose | H17: = IRR n. St. (Eigenkapitalrendite) | I17: =EK_IRR -> 0.053273956
C18: Verlustverrechnung | D18: Sofortige Verrechnung mit anderen Einkünften (Standard Privatperson) | F18: GmbH: immer Verlustvortrag (§ 10d EStG)
H19: Verkauf und Steuern
C20: IMMOBILIENWERT, RESTSCHULD UND NETTOVERMÖGEN | F20: Jahre 1–35 · T€ · Jahresende | H20: =IF(AND(Rechtsform_Idx=1,Haltedauer<=Frist_23),"Verkauf innerhalb der Zehnjahresfrist: Der Veräußerungsgewinn von "&FIXED(Exit_Gewinn,0)&" € ist steuerpflichtig (§ 23 EStG) – die bis dahin genutzte AfA wird über den Buchwert nachversteuert. Eine Haltedauer von mehr als zehn Jahren stellt den Gewinn steuerfrei.",IF(Rechtsform_Idx=1,"Verkauf nach mehr als zehn Jahren: Der Veräußerungsgewinn bleibt im Privatvermögen steuerfrei (§ 23 EStG). Prognosewerte für Miete, Kosten und Wert sind Annahmen – konservative Sätze schützen vor Fehlentscheidungen.","In der GmbH ist der Verkauf unabhängig von der Haltedauer steuerpflichtig; ein Verlustvortrag wird gegengerechnet. Ausschüttungen an die Gesellschafter lösen zusätzlich Abgeltungsteuer bzw. Teileinkünfteverfahren aus.")) -> Verkauf nach mehr als zehn Jahren: Der Veräußerungsgewinn bleibt im Privatvermögen steuerfrei (§ 23 EStG). Prognosewerte für Miete, Kosten und Wert sind Annahmen – konservative Sätze schützen vor Fehlentscheidungen.
H23: =UPPER("IRR n. St. ("&Haltedauer&" J.)") -> IRR N. ST. (12 J.)
H24: =EK_IRR -> 0.053273956
H25: ="Ziel ≥ "&FIXED(Ampel_IRR_gruen*100,1)&" %" -> Ziel ≥ 6.0 % | I25: =IF(AND(ISNUMBER($H$24),$H$24<Ampel_IRR_gelb),"● kritisch",IF(AND(ISNUMBER($H$24),$H$24<Ampel_IRR_gruen),"● prüfen",IF(ISNUMBER($H$24),"● erfüllt",""))) -> ● prüfen
H27: ALS NÄCHSTES | I27: Schritt 12 / 12
H28: Ergebnis · Cashflow nach Steuern, Eigenkapitalrendite, Vermögensaufbau und Zusatzrente nach Volltilgung.
C31: ‹ Zurück: Abschreibung | E31: Übersicht: Leitfaden | H31: Weiter: Ergebnis ›
C33: Keine Gewähr für die Richtigkeit der Angaben · ersetzt keine Rechts-, Steuer- oder Finanzberatung · Rechtsstand September 2026
C34: MM Holding GmbH · Kornhausgasse 4 · 88250 Weingarten · Amtsgericht Ulm HRB 750729

Sheet S12 Ergebnis
C5: SCHRITT 12 / 12 · ERGEBNIS | I5: ‹ Leitfaden
C6: Ergebnis | H6: =Obj_Name -> Beispiel: 3-Zimmer-Eigentumswohnung
C7: Cashflow nach Steuern, Eigenkapitalrendite, Vermögensaufbau und Zusatzrente nach Volltilgung. | H7: =Obj_Adresse&IFERROR(IF(Erstellt_fuer="",""," · Erstellt für "&Erstellt_fuer),"") -> Musterstraße 1, 88250 Weingarten · Erstellt für Max Mustermann
C10: Ergebnis der Kalkulation | H10: IRR n. St. (Eigenkapitalrendite) | I10: =IF(AND(ISNUMBER(EK_IRR),EK_IRR<Ampel_IRR_gelb),"● kritisch"&" · "&FIXED(EK_IRR*100,1)&" %",IF(AND(ISNUMBER(EK_IRR),EK_IRR<Ampel_IRR_gruen),"● prüfen"&" · "&FIXED(EK_IRR*100,1)&" %",IF(ISNUMBER(EK_IRR),"● erfüllt"&" · "&FIXED(EK_IRR*100,1)&" %",""))) -> ● prüfen · 5.3 %
C11: CASHFLOW N. ST. / MONAT (JAHR 1) | E11: STEUERWIRKUNG / MONAT (JAHR 1) | H11: =IFERROR(IF(EK_IRR>=Ampel_IRR_gruen,"Über "&Haltedauer&" Jahre verzinst sich das Eigenkapital mit "&FIXED(EK_IRR*100,1)&" % p. a. nach Steuern – das Ziel von "&FIXED(Ampel_IRR_gruen*100,1)&" % ist erreicht.",IF(EK_IRR>=Ampel_IRR_gelb,"Über "&Haltedauer&" Jahre verzinst sich das Eigenkapital mit "&FIXED(EK_IRR*100,1)&" % p. a. nach Steuern – solide, aber unter dem Ziel von "&FIXED(Ampel_IRR_gruen*100,1)&" %. Hebel: Kaufpreis, Miete, Finanzierung und Haltedauer.","Über "&Haltedauer&" Jahre verzinst sich das Eigenkapital nur mit "&FIXED(EK_IRR*100,1)&" % p. a. nach Steuern – unter der Mindestschwelle von "&FIXED(Ampel_IRR_gelb*100,1)&" %. Kaufpreis, Miete und Finanzierung prüfen.")),"Die Eigenkapitalrendite lässt sich mit diesen Annahmen nicht berechnen.") -> Über 12 Jahre verzinst sich das Eigenkapital mit 5.3 % p. a. nach Steuern – solide, aber unter dem Ziel von 6.0 %. Hebel: Kaufpreis, Miete, Finanzierung und Haltedauer.
C12: =CF_nSt_Monat_J1 -> 256.53305 | E12: =Steuer_J1/12 -> -709.19971
C13: ="ab Jahr 2: "&IF(INDEX(Projektion!$D$37:$AQ$37,2)<0,"−","")&FIXED(ABS(INDEX(Projektion!$D$37:$AQ$37,2)),0)&" €" -> ab Jahr 2: −274 € | D13: =IF($C$12<0,"● kritisch",IF(INDEX(Projektion!$D$37:$AQ$37,2)<0,"● prüfen",IF(ISNUMBER($C$12),"● erfüllt",""))) -> ● prüfen | E13: =IF(Steuer_J1<0,"Erstattung","Zahlung")&" · Cash-Sicht · Steuersatz "&FIXED(Steuersatz_J1*100,2)&" %" -> Erstattung · Cash-Sicht · Steuersatz 46.26 %
C14: EK-RENDITE JAHR 1 | E14: =UPPER("IRR n. St. ("&Haltedauer&" J.)") -> IRR N. ST. (12 J.) | H14: Cashflow nach Steuern
C15: =INDEX(Projektion!$D$45:$AQ$45,1) -> 0.17750535 | E15: =EK_IRR -> 0.053273956 | H15: =IF(CF_nSt_J1>=0,"Nach Steuern bleibt im ersten Jahr ein Überschuss von "&FIXED(CF_nSt_J1/12,0)&" € pro Monat.","Nach Steuern fehlen im ersten Jahr "&FIXED(-CF_nSt_J1/12,0)&" € pro Monat.")&" Der Wert ergibt sich aus der Miete ("&FIXED(INDEX(Projektion!$D$15:$AQ$15,1)/12,0)&" €) abzüglich Rate ("&FIXED(Kapitaldienst_Monat_J1,0)&" €) und Bewirtschaftung ("&FIXED(BWK_J1/12,0)&" €), "&IF(Steuer_J1<0,"zuzüglich Steuererstattung (","abzüglich Steuerzahlung (")&FIXED(ABS(Steuer_J1/12),0)&" €). Über die Tilgung wächst das Nettovermögen jedes Jahr – zusammen mit der Wertentwicklung ergibt sich die Eigenkapitalrendite."&CHAR(10)&CHAR(10)&"Ab "&IF(Darlehen_Summe>0,Volltilgung_Txt,"sofort")&" entfällt die Rate an die Bank – der Cashflow nach Steuern steigt dann auf rund "&FIXED(INDEX(Projektion!$D$37:$AQ$37,MIN(40,IFERROR(MATCH(0,Finanzierung!$D$38:$AQ$38,0),40)+1)),0)&" € pro Monat: die Zusatzrente aus dem Objekt (Prognosewerte)." -> Nach Steuern bleibt im ersten Jahr ein Überschuss von 257 € pro Monat. Der Wert ergibt sich aus der Miete (922 €) abzüglich Rate (1,167 €) und Bewirtschaftung (208 €), zuzüglich Steuererstattung (709 €). Über die Tilgung wächst das Nettovermögen jedes Jahr – zusammen mit der Wertentwicklung ergibt sich die Eigenkapitalrendite. Ab Jahr 32 (2057) entfällt die Rate an die Bank – der Cashflow nach Steuern steigt dann auf rund 805 € pro Monat: die Zusatzrente aus dem Objekt (Prognosewerte).
C16: ="Ziel ≥ "&FIXED(Ampel_EKR_gruen*100,1)&" %"&" · Vermögenszuwachs / Eigenkapital" -> Ziel ≥ 10.0 % · Vermögenszuwachs / Eigenkapital | D16: =IF(AND(ISNUMBER($C$15),$C$15<Ampel_EKR_gelb),"● kritisch",IF(AND(ISNUMBER($C$15),$C$15<Ampel_EKR_gruen),"● prüfen",IF(ISNUMBER($C$15),"● erfüllt",""))) -> ● erfüllt | E16: ="Ziel ≥ "&FIXED(Ampel_IRR_gruen*100,1)&" %"&" · Multiple "&FIXED(EK_Multiple,2)&"×" -> Ziel ≥ 6.0 % · Multiple 1.98× | F16: =IF(AND(ISNUMBER($E$15),$E$15<Ampel_IRR_gelb),"● kritisch",IF(AND(ISNUMBER($E$15),$E$15<Ampel_IRR_gruen),"● prüfen",IF(ISNUMBER($E$15),"● erfüllt",""))) -> ● prüfen
C17: ="NETTOVERMÖGEN NACH "&Haltedauer&" JAHREN" -> NETTOVERMÖGEN NACH 12 JAHREN | E17: ="ZUSATZRENTE / MONAT AB "&IF(Darlehen_Summe>0,UPPER(Volltilgung_Txt),"SOFORT") -> ZUSATZRENTE / MONAT AB JAHR 32 (2057)
C18: =INDEX(Projektion!$D$43:$AQ$43,Haltedauer) -> 196643.25 | E18: =INDEX(Projektion!$D$37:$AQ$37,MIN(40,IFERROR(MATCH(0,Finanzierung!$D$38:$AQ$38,0),40)+1)) -> 804.65546
C19: Immobilienwert abzüglich Restschuld | E19: Cashflow nach Steuern nach Volltilgung (Prognose)
C20: HERLEITUNG PRO MONAT | D20: Jahr 1 | E20: CASHFLOW NACH STEUERN | F20: Jahre 1–30 · T€ p. a. | H20: WEITER ZUR AUSWERTUNG
C21: Cashflow vor Steuern / Monat | D21: =CF_vSt_J1/12 -> -452.66667 | H21: Dashboard – Gesamtbewertung, Ampel, Zeitverlauf ›
C22: ± Steuerwirkung / Monat (+ Erstattung) | D22: =Steuer_J1/12 -> -709.19971 | H22: Cockpit – alle Kennzahlen im Detail ›
C23: = Cashflow nach Steuern / Monat | D23: =CF_nSt_J1/12 -> 256.53305 | H23: Diagramme – Investition, Cashflow, Vermögen ›
C24: Eigenkapitalbedarf inkl. Reserve | D24: =EK_Bedarf_gesamt -> 83974.5 | H24: AfA-Vergleich – Abschreibungsvarianten ›
C25: Gesamtertrag n. St. bis Verkauf | D25: =Gesamtertrag -> 77296.866 | H25: Sensitivität – Break-even und Was-wäre-wenn ›
C26: Eigenkapital-Multiple | D26: =EK_Multiple -> 1.9787573 | H26: Bankgespräch – druckfertige Übersicht ›
C29: ‹ Zurück: Prognose & Exit | E29: Übersicht: Leitfaden | H29: Weiter: Dashboard ›
C31: Keine Gewähr für die Richtigkeit der Angaben · ersetzt keine Rechts-, Steuer- oder Finanzberatung · Rechtsstand September 2026
C32: MM Holding GmbH · Kornhausgasse 4 · 88250 Weingarten · Amtsgericht Ulm HRB 750729

Sheet Dashboard
B5: AUSWERTUNG · GESAMTBEWERTUNG AUF EINER SEITE
B6: Dashboard | K6: =Obj_Name -> Beispiel: 3-Zimmer-Eigentumswohnung
B7: ="Kaufpreis "&FIXED(Kaufpreis,0)&" € · Kauf am "&IFERROR(TEXT(DAY(Kaufdatum),"00")&"."&TEXT(MONTH(Kaufdatum),"00")&"."&YEAR(Kaufdatum),"–")&" · Haltedauer "&Haltedauer&" Jahre · "&Bundesland -> Kaufpreis 285,000 € · Kauf am 01.12.2026 · Haltedauer 12 Jahre · Baden-Württemberg | K7: =Obj_Adresse&IFERROR(IF(Erstellt_fuer="",""," · Erstellt für "&Erstellt_fuer),"") -> Musterstraße 1, 88250 Weingarten · Erstellt für Max Mustermann
B9: ‹ Schritt 12: Ergebnis | E9: Cockpit › | H9: Diagramme › | K9: Sensitivität › | N9: Bankgespräch › | Q9: ="KAUF ALS · "&CHOOSE(Rechtsform_Idx,"Privat","vv-GmbH","GmbH")&" ▾" -> KAUF ALS · Privat ▾
B11: GESAMTBEWERTUNG | E11: =IF(ISNUMBER(SEARCH("kritisch",$B$12)),"● kritisch"&" · "&COUNTIF($H$20:$H$25,"erfüllt")&" von 6 Kennzahlen erfüllt",IF(ISNUMBER(SEARCH("Prüfpunkten",$B$12)),"● prüfen"&" · "&COUNTIF($H$20:$H$25,"erfüllt")&" von 6 Kennzahlen erfüllt",IF($B$12="Solide","● erfüllt"&" · "&COUNTIF($H$20:$H$25,"erfüllt")&" von 6 Kennzahlen erfüllt",""))) -> ● kritisch · 1 von 6 Kennzahlen erfüllt | K11: ="– DSCR (Jahr 1) "&FIXED(DSCR_J1,2)&"×"&IF(DSCR_J1<Ampel_DSCR_gruen," statt mindestens "," bei Ziel ")&FIXED(Ampel_DSCR_gruen,2)&"×"&CHAR(10)&"– IRR n. St. "&FIXED(EK_IRR*100,1)&" % über "&Haltedauer&" Jahre (Ziel "&FIXED(Ampel_IRR_gruen*100,1)&" %)"&CHAR(10)&"– Cashflow n. St. "&FIXED(CF_nSt_Monat_J1,0)&" € / Monat im Jahr 1, ab Jahr 2 "&FIXED(INDEX(Projektion!$D$37:$AQ$37,2),0)&" € / Monat" -> – DSCR (Jahr 1) 0.61× statt mindestens 1.20× – IRR n. St. 5.3 % über 12 Jahre (Ziel 6.0 %) – Cashflow n. St. 257 € / Monat im Jahr 1, ab Jahr 2 -274 € / Monat
B12: =IF(OR($H$23="kritisch",$H$20="kritisch"),"Liquidität kritisch",IF(COUNTIF($H$20:$H$25,"kritisch")>0,"Rendite kritisch",IF(COUNTIF($H$20:$H$25,"prüfen")>0,"Solide mit Prüfpunkten","Solide"))) -> Liquidität kritisch
B14: GESAMTINVESTITION | E14: EIGENKAPITALBEDARF INKL. RESERVE | H14: CASHFLOW N. ST. / MONAT (JAHR 1) | K14: BRUTTOMIETRENDITE | N14: DSCR | Q14: =UPPER("IRR n. St. ("&Haltedauer&" J.)") -> IRR N. ST. (12 J.)
B15: =Gesamtinvestition -> 328974.5 | E15: =EK_Bedarf_gesamt -> 83974.5 | H15: =CF_nSt_Monat_J1 -> 256.53305 | K15: =Bruttomietrendite -> 0.04 | N15: =DSCR_J1 -> 0.612 | Q15: =EK_IRR -> 0.053273956
B16: ="Kaufpreis "&FIXED(Kaufpreis,0)&" € · NK "&FIXED(NK_Quote*100,1)&" %" -> Kaufpreis 285,000 € · NK 10.6 % | E16: ="Quote "&FIXED(EK_Quote*100,1)&" % · Beleihung "&FIXED(Beleihung*100,1)&" %" -> Quote 24.0 % · Beleihung 87.7 % | H16: ="Jahr 2: "&FIXED(INDEX(Projektion!$D$37:$AQ$37,2),0)&" €" -> Jahr 2: -274 € | I16: =IF(CF_nSt_Monat_J1<0,"● kritisch",IF(INDEX(Projektion!$D$37:$AQ$37,2)<0,"● prüfen",IF(ISNUMBER(CF_nSt_Monat_J1),"● erfüllt",""))) -> ● prüfen | K16: ="Faktor "&FIXED(Kaufpreisfaktor,1)&"×" -> Faktor 25.0× | L16: =IF(AND(ISNUMBER(Bruttomietrendite),Bruttomietrendite<Ampel_BMR_gelb),"● kritisch",IF(AND(ISNUMBER(Bruttomietrendite),Bruttomietrendite<Ampel_BMR_gruen),"● prüfen",IF(ISNUMBER(Bruttomietrendite),"● erfüllt",""))) -> ● prüfen | N16: ="Rate "&FIXED(Kapitaldienst_J1/12,0)&" €" -> Rate 1,167 € | O16: =IF(AND(ISNUMBER(DSCR_J1),DSCR_J1<Ampel_DSCR_gelb),"● kritisch",IF(AND(ISNUMBER(DSCR_J1),DSCR_J1<Ampel_DSCR_gruen),"● prüfen",IF(ISNUMBER(DSCR_J1),"● erfüllt",""))) -> ● kritisch | Q16: ="Multiple "&FIXED(EK_Multiple,2)&"×" -> Multiple 1.98× | R16: =IF(AND(ISNUMBER(EK_IRR),EK_IRR<Ampel_IRR_gelb),"● kritisch",IF(AND(ISNUMBER(EK_IRR),EK_IRR<Ampel_IRR_gruen),"● prüfen",IF(ISNUMBER(EK_IRR),"● erfüllt",""))) -> ● prüfen
B18: Kennzahlen-Check | I18: Ist gegen Zielwert | K18: Cashflow Jahr 1 | R18: ■ Zufluss ■ Abfluss ■ Summe · € je Monat
B19: KENNZAHL | E19: IST | F19: ZIEL | H19: STATUS | I19: ERREICHUNG | AK19: Verkaufsmarke (Diagramm Vermögensentwicklung) | AL19: Punkt Nettovermögen im Verkaufsjahr
B20: Cashflow n. St. / Monat | E20: =CF_nSt_Monat_J1 -> 256.53305 | F20: ="≥ 0 €" -> ≥ 0 € | H20: =IF(E20<0,"kritisch",IF(INDEX(Projektion!$D$37:$AQ$37,2)<0,"prüfen","erfüllt")) -> prüfen | I20: =IF(E20>=0,1,0) -> 1 | T20: Miete | U20: =Miete_Ist_J1/12 -> 921.5 | V20: 0 | W20: =V20+U20 -> 921.5 | X20: =IF(MAX(V20,W20)>=0,MAX(MIN(V20,W20),0),0) -> 0 | Y20: =IF(MAX(V20,W20)>=0,0,IF(MAX(V20,W20)+$U$29>=0,MAX(V20,W20),MAX(V20,W20)+$U$29)) -> 0 | Z20: =IF(MAX(V20,W20)>=0,MAX(V20,W20)-MAX(MIN(V20,W20),0),0) -> 921.5 | AA20: =IF(MAX(V20,W20)+$U$29>=0,$U$29,-$U$29) -> 219.86667 | AB20: 0 | AC20: 0 | AD20: 0 | AE20: 0 | AF20: 0 | AG20: 0 | AH20: =IF(MAX(V20,W20)>=0,MIN(MIN(V20,W20),0),MIN(V20,W20)-MAX(V20,W20)) -> 0 | AI20: =IF(U20>=0.5,"+",IF(U20<=-0.5,"−",""))&FIXED(ABS(U20),0) -> +922 | AJ20: =IF(Cockpit!$AB$50="","",IF(LEFT(Cockpit!$AB$50,1)="⚠",0,100)+1) | AK20: =IF(1=Haltedauer,MAX(INDEX(Projektion!$D$41:$AQ$41,1),INDEX(Projektion!$D$43:$AQ$43,1))*1.12,NA()) -> #N/A | AL20: =IF(1=Haltedauer,INDEX(Projektion!$D$43:$AQ$43,1),NA()) -> #N/A
B21: Bruttomietrendite | E21: =Bruttomietrendite -> 0.04 | F21: ="≥ "&FIXED(Ampel_BMR_gruen*100,1)&" %" -> ≥ 5.0 % | H21: =IF(E21>=Ampel_BMR_gruen,"erfüllt",IF(E21>=Ampel_BMR_gelb,"prüfen","kritisch")) -> prüfen | I21: =IF(Ampel_BMR_gruen>0,MIN(MAX(0,E21/Ampel_BMR_gruen),1),IF(E21>=Ampel_BMR_gruen,1,0)) -> 0.8 | T21: Bewirt- schaftung | U21: =-BWK_J1/12 -> -207.5 | V21: =W20 -> 921.5 | W21: =V21+U21 -> 714 | X21: =IF(MAX(V21,W21)>=0,MAX(MIN(V21,W21),0),0) -> 714 | Y21: =IF(MAX(V21,W21)>=0,0,IF(MAX(V21,W21)+$U$29>=0,MAX(V21,W21),MAX(V21,W21)+$U$29)) -> 0 | Z21: =IF(MAX(V21,W21)>=0,MAX(V21,W21)-MAX(MIN(V21,W21),0),0) -> 207.5 | AA21: 0 | AB21: =IF(MAX(V21,W21)+$U$29>=0,$U$29,-$U$29) -> 219.86667 | AC21: 0 | AD21: 0 | AE21: 0 | AF21: 0 | AG21: 0 | AH21: =IF(MAX(V21,W21)>=0,MIN(MIN(V21,W21),0),MIN(V21,W21)-MAX(V21,W21)) -> 0 | AI21: =IF(U21>=0.5,"+",IF(U21<=-0.5,"−",""))&FIXED(ABS(U21),0) -> −208 | AJ21: =IF(Cockpit!$AB$51="","",IF(LEFT(Cockpit!$AB$51,1)="⚠",0,100)+2) | AK21: =IF(2=Haltedauer,MAX(INDEX(Projektion!$D$41:$AQ$41,2),INDEX(Projektion!$D$43:$AQ$43,2))*1.12,NA()) -> #N/A | AL21: =IF(2=Haltedauer,INDEX(Projektion!$D$43:$AQ$43,2),NA()) -> #N/A
