Workbook

Sheet Start
B2: MM Holding | H2: Immobilien-Kalkulation · Version 2.0
B3: Immobilien-Kalkulation | H3: Objekt | I3: Kauf | J3: Investor | K3: Lage | L3: Haltedauer | M3: Stand
H4: =Objekt -> 3-Zi.-ETW, 75 m² | I4: =Kaufdatum -> 46357 | J4: =Investor -> Privatperson | K4: =Lage -> Weingarten | L4: =Haltedauer -> 12 | M4: =Stand -> 46289
B6: Start | C6: Leitfaden | D6: Cockpit | E6: Eingaben | F6: Projektion | G6: Finanzierung | H6: Steuern | I6: AfA-Vergleich | J6: Sensitivität | K6: Bankgespräch | L6: Hinweise | M6: Konfiguration
B8: Objekt | I8: Ergebnis auf einen Blick
B9: Objekt | D9: =Objekt -> 3-Zi.-ETW, 75 m² | I9: Gesamtbewertung | K9: =Cockpit!D8 -> Liquidität kritisch
B10: Lage | D10: =Lage -> Weingarten | I10: Cashflow n. St. / Monat | K10: =CF_Monat_J1 -> 273.68543
B11: Kaufpreis | D11: =Kaufpreis -> 285000 | I11: Kapitaldienstdeckung | K11: =DSCR_J1 -> 0.61353383
B12: Gesamtinvestition | D12: =Gesamtinvestition -> 328974.5 | I12: IRR nach Steuern | K12: =IRR_nSt -> 0.051216806
B13: Kaufdatum | D13: =Kaufdatum -> 46357 | I13: Eigenkapitalbedarf | K13: =Eigenkapital -> 83974.5
B14: Haltedauer | D14: =Haltedauer -> 12 | I14: Nettovermögen Jahr 30 | K14: =Projektion!Q40 -> 525129.15
B16: Inhalt | M16: Klick auf den Blattnamen öffnet das Blatt
B17: Blatt | D17: Bereich | F17: Inhalt
B18: Start | D18: Einstieg | F18: Deckblatt, Inhaltsverzeichnis und Legende
B19: Leitfaden | D19: Einstieg | F19: Schritt-für-Schritt-Anleitung und Konventionen
B20: Cockpit | D20: Ausgabe | F20: Gesamtbewertung, Kennzahlen, Diagramme und Prüfhinweise
B21: Eingaben | D21: Eingabe | F21: Alle Annahmen zu Objekt, Kauf, Finanzierung, Miete, Steuern, Haushalt
B22: Projektion | D22: Berechnung | F22: Jahresprojektion über 30 Jahre, Exit-Rechnung, Renditekennzahlen
B23: Finanzierung | D23: Berechnung | F23: Investitions- und Finanzierungsplan, Tilgungsplan
B24: Steuern | D24: Berechnung | F24: AfA-Bemessung, 15-%-Grenze, Einkünfte aus V+V, Steuereffekt
B25: AfA-Vergleich | D25: Berechnung | F25: Lineare vs. degressive Gebäude-AfA im Vergleich
B26: Sensitivität | D26: Berechnung | F26: Cashflow und DSCR bei veränderten Zinsen und Mieten
B27: Bankgespräch | D27: Bank | F27: Objekt- und Finanzierungsübersicht inkl. Haushaltsrechnung
B28: Hinweise | D28: Anhang | F28: Annahmen, Vereinfachungen, Rechtsgrundlagen, Haftung
B29: Konfiguration | D29: Anhang | F29: Zielwerte, Ampelschwellen, Bankparameter, Auswahllisten
B31: Legende
B32: 12.345 | C32: Eingabe – nur diese Felder ändern (Blatt Eingaben, Konfiguration, Sensitivität) | I32: erfüllt | J32: Ist-Wert erreicht den Zielwert
B33: 12345 | C33: Berechnung – Formel, nicht überschreiben | I33: prüfen | J33: Ist-Wert knapp unter Ziel (ab Schwelle laut Konfiguration)
B34: 12345 | C34: Zwischensumme | I34: kritisch | J34: Ist-Wert deutlich unter Ziel
B35: 12345 | C35: Ergebnis
B37: Keine Gewähr. Ersetzt keine Rechts-, Steuer- oder Finanzberatung · Rechtsstand September 2026 | M37: MM Holding GmbH · Kornhausgasse 4 · 88250 Weingarten · HRB 750729

Sheet Leitfaden
B2: MM Holding | H2: Immobilien-Kalkulation · Version 2.0
B3: Leitfaden
B6: Start | C6: Leitfaden | D6: Cockpit | E6: Eingaben | F6: Projektion | G6: Finanzierung | H6: Steuern | I6: AfA-Vergleich | J6: Sensitivität | K6: Bankgespräch | L6: Hinweise | M6: Konfiguration
B8: In sechs Schritten zur Bewertung
B9: 1 | C9: Eingaben | D9: Alle blau hinterlegten Felder auf dem Blatt „Eingaben“ prüfen und mit den Daten des Objekts überschreiben – Kaufpreis, Nebenkosten, Finanzierungsangebot, Miete, Bewirtschaftung und persönlicher Steuersatz.
B11: 2 | C11: Cockpit | D11: Gesamtbewertung, Kennzahlen-Kacheln und den Kennzahlen-Check lesen. Die Ampel zeigt sofort, ob Liquidität und Rendite den Zielwerten entsprechen.
B13: 3 | C13: Prüfhinweise | D13: Die Hinweise im Cockpit erklären kritische Punkte: Kapitaldienstdeckung, Ende der Zinsbindung, 15-%-Grenze bei Renovierung und Spekulationsfrist.
B15: 4 | C15: Details | D15: Projektion, Finanzierung und Steuern zeigen jede Zahl Jahr für Jahr. Das Verkaufsjahr ist gelb markiert.
B17: 5 | C17: Szenarien | D17: Auf „Sensitivität“ wirken sich Zins- und Mietänderungen sofort auf Cashflow und DSCR aus. Auf „AfA-Vergleich“ werden die Abschreibungsmethoden verglichen.
B19: 6 | C19: Bank | D19: Das Blatt „Bankgespräch“ ist druckfertig (A4 hoch) und fasst Objekt, Finanzierung, Kapitaldienstfähigkeit und Haushaltsrechnung zusammen.
B22: Konventionen
B23: – | C23: Jahr 1 umfasst die ersten 12 Monate ab Kaufdatum; alle Werte sind Jahreswerte, Cockpit-Kacheln teils je Monat.
B24: – | C24: Vorzeichen: Einnahmen positiv, Ausgaben negativ. Steuereffekt: Erstattung positiv, Zahlung negativ.
B25: – | C25: Zielwerte, Ampelschwellen und Bankparameter werden zentral auf „Konfiguration“ gepflegt.
B26: – | C26: Wichtige Größen sind als Namen hinterlegt (z. B. =Gesamtinvestition, =Eigenkapital, =DSCR_J1) – Formeln bleiben lesbar.
B27: – | C27: Schutz vor versehentlichem Überschreiben: Überprüfen → Blatt schützen. Eingabefelder sind bereits entsperrt.
B30: Keine Gewähr. Ersetzt keine Rechts-, Steuer- oder Finanzberatung · Rechtsstand September 2026 | M30: MM Holding GmbH · Kornhausgasse 4 · 88250 Weingarten · HRB 750729

Sheet Cockpit
B2: MM Holding | H2: Immobilien-Kalkulation · Version 2.0
B3: Cockpit | H3: Objekt | I3: Kauf | J3: Investor | K3: Lage | L3: Haltedauer | M3: Stand
H4: =Objekt -> 3-Zi.-ETW, 75 m² | I4: =Kaufdatum -> 46357 | J4: =Investor -> Privatperson | K4: =Lage -> Weingarten | L4: =Haltedauer -> 12 | M4: =Stand -> 46289
B6: Start | C6: Leitfaden | D6: Cockpit | E6: Eingaben | F6: Projektion | G6: Finanzierung | H6: Steuern | I6: AfA-Vergleich | J6: Sensitivität | K6: Bankgespräch | L6: Hinweise | M6: Konfiguration
B8: Gesamtbewertung | D8: =IF(OR(F20="kritisch",F21="kritisch"),"Liquidität kritisch",IF(COUNTIF(F18:F23,"kritisch")>0,"Rendite kritisch",IF(COUNTIF(F18:F23,"prüfen")>0,"Mit Einschränkungen","Solide"))) -> Liquidität kritisch | F8: ="Kapitaldienstdeckung "&FIXED(DSCR_J1,2)&IF(DSCR_J1<Ziel_DSCR," statt mindestens "," bei Ziel ")&FIXED(Ziel_DSCR,2)&". Cashflow nach Steuern im Jahr 1: "&FIXED(CF_Monat_J1,0)&" € / Monat, im Jahr 2: "&FIXED(CF_Monat_J2,0)&" € / Monat. IRR nach Steuern "&FIXED(IRR_nSt*100,1)&" %." -> Kapitaldienstdeckung 0.61 statt mindestens 1.20. Cashflow nach Steuern im Jahr 1: 274 € / Monat, im Jahr 2: -252 € / Monat. IRR nach Steuern 5.1 %.
B11: Gesamtinvestition | D11: Eigenkapitalbedarf | F11: Cashflow n. St. / Monat | H11: Bruttomietrendite | J11: Kapitaldienstdeckung | L11: IRR nach Steuern
B12: =Gesamtinvestition -> 328974.5 | D12: =Eigenkapital -> 83974.5 | F12: =CF_Monat_J1 -> 273.68543 | H12: =Brutto_Rendite -> 0.04 | J12: =DSCR_J1 -> 0.61353383 | L12: =IRR_nSt -> 0.051216806
B14: ="Kaufpreis "&FIXED(Kaufpreis,0)&" €" -> Kaufpreis 285,000 € | D14: ="Quote "&FIXED(EK_Quote*100,1)&" % · LTV "&FIXED(LTV*100,1)&" %" -> Quote 25.5 % · LTV 82.5 % | F14: ="Jahr 2: "&FIXED(CF_Monat_J2,0)&" €" -> Jahr 2: -252 € | H14: ="Faktor "&FIXED(Faktor,1)&"× · netto "&FIXED(Netto_Rendite*100,1)&" %" -> Faktor 25.0× · netto 2.6 % | J14: ="Bankmaßstab ≥ "&FIXED(Ziel_DSCR,2) -> Bankmaßstab ≥ 1.20 | L14: =Haltedauer&" Jahre · Multiple "&FIXED(Multiple,1)&"×" -> 12 Jahre · Multiple 1.7×
B16: Kennzahlen-Check | G16: Ist gegen Ziel | I16: Cashflow Jahr 1 | M16: € je Monat
B17: Kennzahl | D17: Ist | E17: Ziel | F17: Status | G17: Erreichung
B18: Bruttomietrendite | D18: =Brutto_Rendite -> 0.04 | E18: =Ziel_Brutto -> 0.05 | F18: =IF(D18>=E18,"erfüllt",IF(AND(E18>0,D18>=E18*Schwelle_Pruefen),"prüfen","kritisch")) -> prüfen | G18: =REPT("█",ROUND(8*MIN(IF(E18>0,MAX(0,D18/E18),IF(D18>=E18,1.25,0)),1.25),0)) -> ██████
B19: Nettomietrendite | D19: =Netto_Rendite -> 0.026044572 | E19: =Ziel_Netto -> 0.03 | F19: =IF(D19>=E19,"erfüllt",IF(AND(E19>0,D19>=E19*Schwelle_Pruefen),"prüfen","kritisch")) -> prüfen | G19: =REPT("█",ROUND(8*MIN(IF(E19>0,MAX(0,D19/E19),IF(D19>=E19,1.25,0)),1.25),0)) -> ███████
B20: Kapitaldienstdeckung | D20: =DSCR_J1 -> 0.61353383 | E20: =Ziel_DSCR -> 1.2 | F20: =IF(D20>=E20,"erfüllt",IF(AND(E20>0,D20>=E20*Schwelle_Pruefen),"prüfen","kritisch")) -> kritisch | G20: =REPT("█",ROUND(8*MIN(IF(E20>0,MAX(0,D20/E20),IF(D20>=E20,1.25,0)),1.25),0)) -> ████
B21: Cashflow n. St. / Monat | D21: =CF_Monat_J1 -> 273.68543 | E21: =Ziel_CF -> 0 | F21: =IF(D21>=E21,"erfüllt",IF(AND(E21>0,D21>=E21*Schwelle_Pruefen),"prüfen","kritisch")) -> erfüllt | G21: =REPT("█",ROUND(8*MIN(IF(E21>0,MAX(0,D21/E21),IF(D21>=E21,1.25,0)),1.25),0)) -> ██████████
B22: EK-Rendite Jahr 1 | D22: =EK_Rendite_J1 -> 0.1681966 | E22: =Ziel_EKR -> 0.1 | F22: =IF(D22>=E22,"erfüllt",IF(AND(E22>0,D22>=E22*Schwelle_Pruefen),"prüfen","kritisch")) -> erfüllt | G22: =REPT("█",ROUND(8*MIN(IF(E22>0,MAX(0,D22/E22),IF(D22>=E22,1.25,0)),1.25),0)) -> ██████████
B23: IRR nach Steuern | D23: =IRR_nSt -> 0.051216806 | E23: =Ziel_IRR -> 0.06 | F23: =IF(D23>=E23,"erfüllt",IF(AND(E23>0,D23>=E23*Schwelle_Pruefen),"prüfen","kritisch")) -> prüfen | G23: =REPT("█",ROUND(8*MIN(IF(E23>0,MAX(0,D23/E23),IF(D23>=E23,1.25,0)),1.25),0)) -> ███████
B24: Balken: 8 Blöcke = Zielwert erreicht · Ziele und Ampelschwellen: Blatt Konfiguration
B27: Vermögensentwicklung | G27: € · Jahre 1–30 | I27: Prüfhinweise | M27: =COUNTIF(I28:I37,"●*")&" Warnung(en)" -> 2 Warnung(en)
I28: =IF(DSCR_J1<Ziel_DSCR,"● DSCR im Jahr 1 nur "&FIXED(DSCR_J1,2)&" – Banken erwarten meist 1,10 bis 1,20.","○ DSCR im Jahr 1 "&FIXED(DSCR_J1,2)&" – Bankmaßstab erfüllt.") -> ● DSCR im Jahr 1 nur 0.61 – Banken erwarten meist 1,10 bis 1,20.
I30: =IF(Zinsbindung<Haltedauer,"● ","○ ")&"Zinsbindung endet nach "&Zinsbindung&" Jahren, Restschuld "&FIXED(Restschuld_ZB,0)&" € – Anschlusszins "&FIXED(Anschlusszins*100,2)&" % angenommen." -> ● Zinsbindung endet nach 10 Jahren, Restschuld 186,982 € – Anschlusszins 4.50 % angenommen.
I32: ="○ Steuerliches Ergebnis Jahr 1 "&FIXED(Steuern!I23,0)&" € – "&IF(Steuern!I23<0,"Verrechnung mit anderen Einkünften.","zu versteuern.") -> ○ Steuerliches Ergebnis Jahr 1 -19,592 € – Verrechnung mit anderen Einkünften.
I34: =IF(Regel15_ok=1,"○ Renovierung "&FIXED(Renovierung,0)&" € unter der 15-%-Grenze ("&FIXED(Grenze15,0)&" €) – sofort abziehbar.","● Renovierung über der 15-%-Grenze ("&FIXED(Grenze15,0)&" €) – nur über die AfA absetzbar.") -> ○ Renovierung 14,250 € unter der 15-%-Grenze (36,753 €) – sofort abziehbar.
I36: =IF(Haltedauer<=10,"● Verkauf innerhalb von 10 Jahren – Veräußerungsgewinn steuerpflichtig (§ 23 EStG).","○ Bewegliche Gegenstände "&FIXED(Inventar,0)&" € – grunderwerbsteuerfrei, "&ND_Inventar&" Jahre AfA.") -> ○ Bewegliche Gegenstände 8,000 € – grunderwerbsteuerfrei, 10 Jahre AfA.
B39: Kennzahlen im Zeitverlauf | M39: € p. a.
B40: Jahr | E40: 1 | F40: 2 | G40: 3 | H40: 5 | I40: 10 | J40: 15 | K40: 20 | L40: 25 | M40: 30
B41: Nettokaltmiete Ist | E41: =INDEX(Projektion!$E$11:$E$40,E$40) -> 11058 | F41: =INDEX(Projektion!$E$11:$E$40,F$40) -> 11279.16 | G41: =INDEX(Projektion!$E$11:$E$40,G$40) -> 11504.743 | H41: =INDEX(Projektion!$E$11:$E$40,H$40) -> 11969.535 | I41: =INDEX(Projektion!$E$11:$E$40,I$40) -> 13215.334 | J41: =INDEX(Projektion!$E$11:$E$40,J$40) -> 14590.796 | K41: =INDEX(Projektion!$E$11:$E$40,K$40) -> 16109.418 | L41: =INDEX(Projektion!$E$11:$E$40,L$40) -> 17786.099 | M41: =INDEX(Projektion!$E$11:$E$40,M$40) -> 19637.291
B42: Bewirtschaftungskosten | E42: =INDEX(Projektion!$F$11:$F$40,E$40) -> -2490 | F42: =INDEX(Projektion!$F$11:$F$40,F$40) -> -2539.8 | G42: =INDEX(Projektion!$F$11:$F$40,G$40) -> -2590.596 | H42: =INDEX(Projektion!$F$11:$F$40,H$40) -> -2695.2561 | I42: =INDEX(Projektion!$F$11:$F$40,I$40) -> -2975.7805 | J42: =INDEX(Projektion!$F$11:$F$40,J$40) -> -3285.5021 | K42: =INDEX(Projektion!$F$11:$F$40,K$40) -> -3627.4598 | L42: =INDEX(Projektion!$F$11:$F$40,L$40) -> -4005.0088 | M42: =INDEX(Projektion!$F$11:$F$40,M$40) -> -4421.8533
B43: Kapitaldienst | E43: =INDEX(Projektion!$I$11:$I$40,E$40) -> -13965 | F43: =INDEX(Projektion!$I$11:$I$40,F$40) -> -13965 | G43: =INDEX(Projektion!$I$11:$I$40,G$40) -> -13965 | H43: =INDEX(Projektion!$I$11:$I$40,H$40) -> -13965 | I43: =INDEX(Projektion!$I$11:$I$40,I$40) -> -13965 | J43: =INDEX(Projektion!$I$11:$I$40,J$40) -> -13965 | K43: =INDEX(Projektion!$I$11:$I$40,K$40) -> -13965 | L43: =INDEX(Projektion!$I$11:$I$40,L$40) -> -13965 | M43: =INDEX(Projektion!$I$11:$I$40,M$40) -> -13965
B44: Cashflow vor Steuern | E44: =INDEX(Projektion!$J$11:$J$40,E$40) -> -5397 | F44: =INDEX(Projektion!$J$11:$J$40,F$40) -> -5225.64 | G44: =INDEX(Projektion!$J$11:$J$40,G$40) -> -5050.8528 | H44: =INDEX(Projektion!$J$11:$J$40,H$40) -> -4690.7213 | I44: =INDEX(Projektion!$J$11:$J$40,I$40) -> -3725.4469 | J44: =INDEX(Projektion!$J$11:$J$40,J$40) -> -2659.706 | K44: =INDEX(Projektion!$J$11:$J$40,K$40) -> -1483.0419 | L44: =INDEX(Projektion!$J$11:$J$40,L$40) -> -183.90965 | M44: =INDEX(Projektion!$J$11:$J$40,M$40) -> 1250.4373
B45: Steuereffekt | E45: =INDEX(Projektion!$K$11:$K$40,E$40) -> 8681.2251 | F45: =INDEX(Projektion!$K$11:$K$40,F$40) -> 2202.8107 | G45: =INDEX(Projektion!$K$11:$K$40,G$40) -> 2033.9208 | H45: =INDEX(Projektion!$K$11:$K$40,H$40) -> 1681.6106 | I45: =INDEX(Projektion!$K$11:$K$40,I$40) -> 708.80252 | J45: =INDEX(Projektion!$K$11:$K$40,J$40) -> -109.3596 | K45: =INDEX(Projektion!$K$11:$K$40,K$40) -> -1407.5764 | L45: =INDEX(Projektion!$K$11:$K$40,L$40) -> -2943.5196 | M45: =INDEX(Projektion!$K$11:$K$40,M$40) -> -4767.192
B46: Cashflow nach Steuern | E46: =INDEX(Projektion!$L$11:$L$40,E$40) -> 3284.2251 | F46: =INDEX(Projektion!$L$11:$L$40,F$40) -> -3022.8293 | G46: =INDEX(Projektion!$L$11:$L$40,G$40) -> -3016.932 | H46: =INDEX(Projektion!$L$11:$L$40,H$40) -> -3009.1106 | I46: =INDEX(Projektion!$L$11:$L$40,I$40) -> -3016.6444 | J46: =INDEX(Projektion!$L$11:$L$40,J$40) -> -2769.0656 | K46: =INDEX(Projektion!$L$11:$L$40,K$40) -> -2890.6183 | L46: =INDEX(Projektion!$L$11:$L$40,L$40) -> -3127.4293 | M46: =INDEX(Projektion!$L$11:$L$40,M$40) -> -3516.7547
B47: Kumulierter Cashflow nach Steuern | E47: =INDEX(Projektion!$M$11:$M$40,E$40) -> 3284.2251 | F47: =INDEX(Projektion!$M$11:$M$40,F$40) -> 261.3958 | G47: =INDEX(Projektion!$M$11:$M$40,G$40) -> -2755.5362 | H47: =INDEX(Projektion!$M$11:$M$40,H$40) -> -8776.9799 | I47: =INDEX(Projektion!$M$11:$M$40,I$40) -> -23828.318 | J47: =INDEX(Projektion!$M$11:$M$40,J$40) -> -37573.18 | K47: =INDEX(Projektion!$M$11:$M$40,K$40) -> -51743.433 | L47: =INDEX(Projektion!$M$11:$M$40,L$40) -> -66854.062 | M47: =INDEX(Projektion!$M$11:$M$40,M$40) -> -83589.538
B48: Abschreibungen gesamt | E48: =INDEX(Projektion!$N$11:$N$40,E$40) -> 5745.0224 | F48: =INDEX(Projektion!$N$11:$N$40,F$40) -> 5745.0224 | G48: =INDEX(Projektion!$N$11:$N$40,G$40) -> 5745.0224 | H48: =INDEX(Projektion!$N$11:$N$40,H$40) -> 5745.0224 | I48: =INDEX(Projektion!$N$11:$N$40,I$40) -> 5745.0224 | J48: =INDEX(Projektion!$N$11:$N$40,J$40) -> 4900.4624 | K48: =INDEX(Projektion!$N$11:$N$40,K$40) -> 4900.4624 | L48: =INDEX(Projektion!$N$11:$N$40,L$40) -> 4900.4624 | M48: =INDEX(Projektion!$N$11:$N$40,M$40) -> 4900.4624
B49: Immobilienwert Jahresende | E49: =INDEX(Projektion!$O$11:$O$40,E$40) -> 302940 | F49: =INDEX(Projektion!$O$11:$O$40,F$40) -> 308998.8 | G49: =INDEX(Projektion!$O$11:$O$40,G$40) -> 315178.78 | H49: =INDEX(Projektion!$O$11:$O$40,H$40) -> 327912 | I49: =INDEX(Projektion!$O$11:$O$40,I$40) -> 362041.34 | J49: =INDEX(Projektion!$O$11:$O$40,J$40) -> 399722.9 | K49: =INDEX(Projektion!$O$11:$O$40,K$40) -> 441326.38 | L49: =INDEX(Projektion!$O$11:$O$40,L$40) -> 487259.98 | M49: =INDEX(Projektion!$O$11:$O$40,M$40) -> 537974.39
B50: Restschuld Jahresende | E50: =INDEX(Projektion!$P$11:$P$40,E$40) -> 240100 | F50: =INDEX(Projektion!$P$11:$P$40,F$40) -> 235018.7 | G50: =INDEX(Projektion!$P$11:$P$40,G$40) -> 229749.39 | H50: =INDEX(Projektion!$P$11:$P$40,H$40) -> 218618.67 | I50: =INDEX(Projektion!$P$11:$P$40,I$40) -> 186982.02 | J50: =INDEX(Projektion!$P$11:$P$40,J$40) -> 156615.15 | K50: =INDEX(Projektion!$P$11:$P$40,K$40) -> 118772.51 | L50: =INDEX(Projektion!$P$11:$P$40,L$40) -> 71613.7 | M50: =INDEX(Projektion!$P$11:$P$40,M$40) -> 12845.238
B51: Nettovermögen | E51: =INDEX(Projektion!$Q$11:$Q$40,E$40) -> 62840 | F51: =INDEX(Projektion!$Q$11:$Q$40,F$40) -> 73980.1 | G51: =INDEX(Projektion!$Q$11:$Q$40,G$40) -> 85429.384 | H51: =INDEX(Projektion!$Q$11:$Q$40,H$40) -> 109293.33 | I51: =INDEX(Projektion!$Q$11:$Q$40,I$40) -> 175059.32 | J51: =INDEX(Projektion!$Q$11:$Q$40,J$40) -> 243107.74 | K51: =INDEX(Projektion!$Q$11:$Q$40,K$40) -> 322553.86 | L51: =INDEX(Projektion!$Q$11:$Q$40,L$40) -> 415646.28 | M51: =INDEX(Projektion!$Q$11:$Q$40,M$40) -> 525129.15
B52: Jahr 1 = 12 Monate ab Kaufdatum · Steuereffekt: Erstattung positiv, Zahlung negativ · Details: Blatt Projektion
B54: Keine Gewähr. Ersetzt keine Rechts-, Steuer- oder Finanzberatung · Rechtsstand September 2026 | M54: MM Holding GmbH · Kornhausgasse 4 · 88250 Weingarten · HRB 750729

Sheet Eingaben
B2: MM Holding | H2: Immobilien-Kalkulation · Version 2.0
B3: Eingaben
B6: Start | C6: Leitfaden | D6: Cockpit | E6: Eingaben | F6: Projektion | G6: Finanzierung | H6: Steuern | I6: AfA-Vergleich | J6: Sensitivität | K6: Bankgespräch | L6: Hinweise | M6: Konfiguration
B8: Eingabe | C8: Blau hinterlegte Felder sind Eingaben – alle übrigen Blätter rechnen automatisch. Die Werte sind ein Beispiel (3-Zi.-ETW in Weingarten).
B10: Parameter | E10: Wert | F10: Einheit | G10: Hinweis / Quelle
B12: Objekt und Rahmendaten
B13: Objektbezeichnung | E13: 3-Zi.-ETW, 75 m² | G13: Erscheint in Kopfzeilen und im Bankgespräch
B14: Lage | E14: Weingarten
B15: Investor | E15: Privatperson | G15: Steuerlogik: Privatvermögen, Einkünfte aus Vermietung und Verpachtung (§ 21 EStG)
B16: Wohnfläche | E16: 75 | F16: m² | G16: Laut Teilungserklärung / Wohnflächenberechnung
B17: Kaufdatum (Übergang Nutzen und Lasten) | E17: 46357 | F17: Datum | G17: Jahr 1 = 12 Monate ab diesem Datum
B18: Stand der Kalkulation | E18: 46289 | F18: Datum
B19: Geplante Haltedauer | E19: 12 | F19: Jahre | G19: Verkauf nach mehr als 10 Jahren steuerfrei (§ 23 EStG)
B21: Kaufpreis und Nebenkosten
B22: Kaufpreis | E22: 285000 | F22: € | G22: Laut Kaufvertrag
B23: davon bewegl. Gegenstände (Küche, Inventar) | E23: 8000 | F23: € | G23: Grunderwerbsteuerfrei, eigene AfA – Wert angemessen belegen
B24: Grunderwerbsteuer | E24: 0.05 | F24: % | G24: Baden-Württemberg 5,0 %; Bemessung ohne bewegliche Gegenstände
B25: Notar | E25: 0.015 | F25: % | G25: Richtwert ca. 1,5 % des Kaufpreises
B26: Grundbuch | E26: 0.005 | F26: % | G26: Richtwert ca. 0,5 % des Kaufpreises
B27: Makler (inkl. USt.) | E27: 0.0357 | F27: % | G27: Käuferanteil laut Exposé
B28: Renovierung nach Kauf (netto) | E28: 14250 | F28: € | G28: Nettobetrag der ersten 3 Jahre – 15-%-Grenze prüft Blatt „Steuern“
B29: Verteilung Erhaltungsaufwand | E29: 1 | F29: Jahre | G29: 1 = sofort abziehen; 2–5 Jahre nach § 82b EStDV möglich
B31: Finanzierung
B32: Darlehensbetrag | E32: 245000 | F32: € | G32: Annuitätendarlehen, konstante Rate über die gesamte Laufzeit
B33: Sollzins p. a. | E33: 0.037 | F33: % | G33: Laut Finanzierungsangebot
B34: Anfängliche Tilgung p. a. | E34: 0.02 | F34: %
B35: Zinsbindung | E35: 10 | F35: Jahre
B36: Anschlusszins (Annahme) | E36: 0.045 | F36: % | G36: Annahme für die Zeit nach Ende der Zinsbindung
B38: Miete und Bewirtschaftung
B39: Nettokaltmiete Soll | E39: 950 | F39: €/Monat | G39: Laut Mietvertrag bzw. Mietspiegel
B40: Mietausfallwagnis | E40: 0.03 | F40: % | G40: Leerstand und Zahlungsausfälle
B41: Mietsteigerung p. a. | E41: 0.02 | F41: %
B42: Hausgeld nicht umlagefähig | E42: 1290 | F42: €/Jahr | G42: WEG-Verwaltung, Bankgebühren etc. – steuerlich abziehbar
B43: Instandhaltungsrücklage | E43: 900 | F43: €/Jahr | G43: Liquiditätswirksam; steuerlich erst bei Verwendung abziehbar
B44: Sondereigentumsverwaltung / Sonstiges | E44: 300 | F44: €/Jahr | G44: Steuerlich abziehbar
B45: Kostensteigerung p. a. | E45: 0.02 | F45: %
B47: Wertentwicklung und Verkauf
B48: Marktwert bei Kauf | E48: 297000 | F48: € | G48: Annahme laut Bewertung / Gutachten
B49: Wertsteigerung p. a. | E49: 0.02 | F49: %
B50: Verkaufskosten bei Exit | E50: 0.03 | F50: % | G50: Makler, Notar u. Ä. beim Verkauf
...

Sheet Projektion
B2: MM Holding | H2: Immobilien-Kalkulation · Version 2.0
B3: Projektion
B6: Start | C6: Leitfaden | D6: Cockpit | E6: Eingaben | F6: Projektion | G6: Finanzierung | H6: Steuern | I6: AfA-Vergleich | J6: Sensitivität | K6: Bankgespräch | L6: Hinweise | M6: Konfiguration
B8: Jahresprojektion | T8: € p. a. · Jahr 1 = 12 Monate ab Kaufdatum
B9: Jahr | C9: Nettokaltmiete Soll | D9: Mietausfall | E9: Nettokaltmiete Ist | F9: Bewirtschaftung | G9: Zinsen | H9: Tilgung | I9: Kapitaldienst | J9: Cashflow vor Steuern | K9: Steuereffekt | L9: Cashflow nach Steuern | M9: CF n. St. kumuliert | N9: Abschreibungen gesamt | O9: Immobilienwert Jahresende | P9: Restschuld Jahresende | Q9: Nettovermögen | R9: DSCR | S9: Netto-Exit-Erlös | T9: Zahlungsstrom Eigenkapital
B10: 0 | O10: =Marktwert -> 297000 | P10: =Darlehen -> 245000 | Q10: =O10-P10 -> 52000 | T10: =-Eigenkapital -> -83974.5
B11: 1 | C11: =Miete_Monat*12*(1+Mietsteigerung)^(B11-1) -> 11400 | D11: =-C11*Mietausfall -> -342 | E11: =C11+D11 -> 11058 | F11: =-(Hausgeld_nu+Ruecklage+Verwaltung)*(1+Kostensteigerung)^(B11-1) -> -2490 | G11: =-Finanzierung!E20 -> -9065 | H11: =-Finanzierung!F20 -> -4900 | I11: =G11+H11 -> -13965 | J11: =E11+F11+I11 -> -5397 | K11: =Steuern!J23 -> 8681.2251 | L11: =J11+K11 -> 3284.2251 | M11: =SUM(L$11:L11) -> 3284.2251 | N11: =Steuern!L23 -> 5745.0224 | O11: =Marktwert*(1+Wertsteigerung)^B11 -> 302940 | P11: =Finanzierung!H20 -> 240100 | Q11: =O11-P11 -> 62840 | R11: =IF(I11=0,"",(E11+F11)/-I11) -> 0.61353383 | S11: =IF(B11=Haltedauer,Exit_Netto,0) -> 0 | T11: =IF(B11<=Haltedauer,L11+S11,0) -> 3284.2251
B12: 2 | C12: =Miete_Monat*12*(1+Mietsteigerung)^(B12-1) -> 11628 | D12: =-C12*Mietausfall -> -348.84 | E12: =C12+D12 -> 11279.16 | F12: =-(Hausgeld_nu+Ruecklage+Verwaltung)*(1+Kostensteigerung)^(B12-1) -> -2539.8 | G12: =-Finanzierung!E21 -> -8883.7 | H12: =-Finanzierung!F21 -> -5081.3 | I12: =G12+H12 -> -13965 | J12: =E12+F12+I12 -> -5225.64 | K12: =Steuern!J24 -> 2202.8107 | L12: =J12+K12 -> -3022.8293 | M12: =SUM(L$11:L12) -> 261.3958 | N12: =Steuern!L24 -> 5745.0224 | O12: =Marktwert*(1+Wertsteigerung)^B12 -> 308998.8 | P12: =Finanzierung!H21 -> 235018.7 | Q12: =O12-P12 -> 73980.1 | R12: =IF(I12=0,"",(E12+F12)/-I12) -> 0.62580451 | S12: =IF(B12=Haltedauer,Exit_Netto,0) -> 0 | T12: =IF(B12<=Haltedauer,L12+S12,0) -> -3022.8293
B13: 3 | C13: =Miete_Monat*12*(1+Mietsteigerung)^(B13-1) -> 11860.56 | D13: =-C13*Mietausfall -> -355.8168 | E13: =C13+D13 -> 11504.743 | F13: =-(Hausgeld_nu+Ruecklage+Verwaltung)*(1+Kostensteigerung)^(B13-1) -> -2590.596 | G13: =-Finanzierung!E22 -> -8695.6919 | H13: =-Finanzierung!F22 -> -5269.3081 | I13: =G13+H13 -> -13965 | J13: =E13+F13+I13 -> -5050.8528 | K13: =Steuern!J25 -> 2033.9208 | L13: =J13+K13 -> -3016.932 | M13: =SUM(L$11:L13) -> -2755.5362 | N13: =Steuern!L25 -> 5745.0224 | O13: =Marktwert*(1+Wertsteigerung)^B13 -> 315178.78 | P13: =Finanzierung!H22 -> 229749.39 | Q13: =O13-P13 -> 85429.384 | R13: =IF(I13=0,"",(E13+F13)/-I13) -> 0.6383206 | S13: =IF(B13=Haltedauer,Exit_Netto,0) -> 0 | T13: =IF(B13<=Haltedauer,L13+S13,0) -> -3016.932
B14: 4 | C14: =Miete_Monat*12*(1+Mietsteigerung)^(B14-1) -> 12097.771 | D14: =-C14*Mietausfall -> -362.93314 | E14: =C14+D14 -> 11734.838 | F14: =-(Hausgeld_nu+Ruecklage+Verwaltung)*(1+Kostensteigerung)^(B14-1) -> -2642.4079 | G14: =-Finanzierung!E23 -> -8500.7275 | H14: =-Finanzierung!F23 -> -5464.2725 | I14: =G14+H14 -> -13965 | J14: =E14+F14+I14 -> -4872.5699 | K14: =Steuern!J26 -> 1860.2368 | L14: =J14+K14 -> -3012.333 | M14: =SUM(L$11:L14) -> -5767.8692 | N14: =Steuern!L26 -> 5745.0224 | O14: =Marktwert*(1+Wertsteigerung)^B14 -> 321482.35 | P14: =Finanzierung!H23 -> 224285.12 | Q14: =O14-P14 -> 97197.232 | R14: =IF(I14=0,"",(E14+F14)/-I14) -> 0.65108701 | S14: =IF(B14=Haltedauer,Exit_Netto,0) -> 0 | T14: =IF(B14<=Haltedauer,L14+S14,0) -> -3012.333
B15: 5 | C15: =Miete_Monat*12*(1+Mietsteigerung)^(B15-1) -> 12339.727 | D15: =-C15*Mietausfall -> -370.1918 | E15: =C15+D15 -> 11969.535 | F15: =-(Hausgeld_nu+Ruecklage+Verwaltung)*(1+Kostensteigerung)^(B15-1) -> -2695.2561 | G15: =-Finanzierung!E24 -> -8298.5494 | H15: =-Finanzierung!F24 -> -5666.4506 | I15: =G15+H15 -> -13965 | J15: =E15+F15+I15 -> -4690.7213 | K15: =Steuern!J27 -> 1681.6106 | L15: =J15+K15 -> -3009.1106 | M15: =SUM(L$11:L15) -> -8776.9799 | N15: =Steuern!L27 -> 5745.0224 | O15: =Marktwert*(1+Wertsteigerung)^B15 -> 327912 | P15: =Finanzierung!H24 -> 218618.67 | Q15: =O15-P15 -> 109293.33 | R15: =IF(I15=0,"",(E15+F15)/-I15) -> 0.66410875 | S15: =IF(B15=Haltedauer,Exit_Netto,0) -> 0 | T15: =IF(B15<=Haltedauer,L15+S15,0) -> -3009.1106
B16: 6 | C16: =Miete_Monat*12*(1+Mietsteigerung)^(B16-1) -> 12586.521 | D16: =-C16*Mietausfall -> -377.59563 | E16: =C16+D16 -> 12208.926 | F16: =-(Hausgeld_nu+Ruecklage+Verwaltung)*(1+Kostensteigerung)^(B16-1) -> -2749.1612 | G16: =-Finanzierung!E25 -> -8088.8907 | H16: =-Finanzierung!F25 -> -5876.1093 | I16: =G16+H16 -> -13965 | J16: =E16+F16+I16 -> -4505.2357 | K16: =Steuern!J28 -> 1497.889 | L16: =J16+K16 -> -3007.3467 | M16: =SUM(L$11:L16) -> -11784.327 | N16: =Steuern!L28 -> 5745.0224 | O16: =Marktwert*(1+Wertsteigerung)^B16 -> 334470.24 | P16: =Finanzierung!H25 -> 212742.56 | Q16: =O16-P16 -> 121727.68 | R16: =IF(I16=0,"",(E16+F16)/-I16) -> 0.67739093 | S16: =IF(B16=Haltedauer,Exit_Netto,0) -> 0 | T16: =IF(B16<=Haltedauer,L16+S16,0) -> -3007.3467
B17: 7 | C17: =Miete_Monat*12*(1+Mietsteigerung)^(B17-1) -> 12838.252 | D17: =-C17*Mietausfall -> -385.14755 | E17: =C17+D17 -> 12453.104 | F17: =-(Hausgeld_nu+Ruecklage+Verwaltung)*(1+Kostensteigerung)^(B17-1) -> -2804.1444 | G17: =-Finanzierung!E26 -> -7871.4747 | H17: =-Finanzierung!F26 -> -6093.5253 | I17: =G17+H17 -> -13965 | J17: =E17+F17+I17 -> -4316.0404 | K17: =Steuern!J29 -> 1308.9136 | L17: =J17+K17 -> -3007.1268 | M17: =SUM(L$11:L17) -> -14791.453 | N17: =Steuern!L29 -> 5745.0224 | O17: =Marktwert*(1+Wertsteigerung)^B17 -> 341159.64 | P17: =Finanzierung!H26 -> 206649.03 | Q17: =O17-P17 -> 134510.61 | R17: =IF(I17=0,"",(E17+F17)/-I17) -> 0.69093875 | S17: =IF(B17=Haltedauer,Exit_Netto,0) -> 0 | T17: =IF(B17<=Haltedauer,L17+S17,0) -> -3007.1268
B18: 8 | C18: =Miete_Monat*12*(1+Mietsteigerung)^(B18-1) -> 13095.017 | D18: =-C18*Mietausfall -> -392.8505 | E18: =C18+D18 -> 12702.166 | F18: =-(Hausgeld_nu+Ruecklage+Verwaltung)*(1+Kostensteigerung)^(B18-1) -> -2860.2273 | G18: =-Finanzierung!E27 -> -7646.0143 | H18: =-Finanzierung!F27 -> -6318.9857 | I18: =G18+H18 -> -13965 | J18: =E18+F18+I18 -> -4123.0612 | K18: =Steuern!J30 -> 1114.5209 | L18: =J18+K18 -> -3008.5403 | M18: =SUM(L$11:L18) -> -17799.994 | N18: =Steuern!L30 -> 5745.0224 | O18: =Marktwert*(1+Wertsteigerung)^B18 -> 347982.84 | P18: =Finanzierung!H27 -> 200330.05 | Q18: =O18-P18 -> 147652.79 | R18: =IF(I18=0,"",(E18+F18)/-I18) -> 0.70475752 | S18: =IF(B18=Haltedauer,Exit_Netto,0) -> 0 | T18: =IF(B18<=Haltedauer,L18+S18,0) -> -3008.5403
B19: 9 | C19: =Miete_Monat*12*(1+Mietsteigerung)^(B19-1) -> 13356.917 | D19: =-C19*Mietausfall -> -400.70751 | E19: =C19+D19 -> 12956.209 | F19: =-(Hausgeld_nu+Ruecklage+Verwaltung)*(1+Kostensteigerung)^(B19-1) -> -2917.4319 | G19: =-Finanzierung!E28 -> -7412.2118 | H19: =-Finanzierung!F28 -> -6552.7882 | I19: =G19+H19 -> -13965 | J19: =E19+F19+I19 -> -3926.2224 | K19: =Steuern!J31 -> 914.54208 | L19: =J19+K19 -> -3011.6803 | M19: =SUM(L$11:L19) -> -20811.674 | N19: =Steuern!L31 -> 5745.0224 | O19: =Marktwert*(1+Wertsteigerung)^B19 -> 354942.49 | P19: =Finanzierung!H28 -> 193777.26 | Q19: =O19-P19 -> 161165.23 | R19: =IF(I19=0,"",(E19+F19)/-I19) -> 0.71885267 | S19: =IF(B19=Haltedauer,Exit_Netto,0) -> 0 | T19: =IF(B19<=Haltedauer,L19+S19,0) -> -3011.6803
B20: 10 | C20: =Miete_Monat*12*(1+Mietsteigerung)^(B20-1) -> 13624.055 | D20: =-C20*Mietausfall -> -408.72166 | E20: =C20+D20 -> 13215.334 | F20: =-(Hausgeld_nu+Ruecklage+Verwaltung)*(1+Kostensteigerung)^(B20-1) -> -2975.7805 | G20: =-Finanzierung!E29 -> -7169.7586 | H20: =-Finanzierung!F29 -> -6795.2414 | I20: =G20+H20 -> -13965 | J20: =E20+F20+I20 -> -3725.4469 | K20: =Steuern!J32 -> 708.80252 | L20: =J20+K20 -> -3016.6444 | M20: =SUM(L$11:L20) -> -23828.318 | N20: =Steuern!L32 -> 5745.0224 | O20: =Marktwert*(1+Wertsteigerung)^B20 -> 362041.34 | P20: =Finanzierung!H29 -> 186982.02 | Q20: =O20-P20 -> 175059.32 | R20: =IF(I20=0,"",(E20+F20)/-I20) -> 0.73322973 | S20: =IF(B20=Haltedauer,Exit_Netto,0) -> 0 | T20: =IF(B20<=Haltedauer,L20+S20,0) -> -3016.6444
B21: 11 | C21: =Miete_Monat*12*(1+Mietsteigerung)^(B21-1) -> 13896.536 | D21: =-C21*Mietausfall -> -416.89609 | E21: =C21+D21 -> 13479.64 | F21: =-(Hausgeld_nu+Ruecklage+Verwaltung)*(1+Kostensteigerung)^(B21-1) -> -3035.2961 | G21: =-Finanzierung!E30 -> -8414.1909 | H21: =-Finanzierung!F30 -> -5550.8091 | I21: =G21+H21 -> -13965 | J21: =E21+F21+I21 -> -3520.6558 | K21: =Steuern!J33 -> 785.71116 | L21: =J21+K21 -> -2734.9446 | M21: =SUM(L$11:L21) -> -26563.263 | N21: =Steuern!L33 -> 4900.4624 | O21: =Marktwert*(1+Wertsteigerung)^B21 -> 369282.17 | P21: =Finanzierung!H30 -> 181431.21 | Q21: =O21-P21 -> 187850.96 | R21: =IF(I21=0,"",(E21+F21)/-I21) -> 0.74789432 | S21: =IF(B21=Haltedauer,Exit_Netto,0) -> 0 | T21: =IF(B21<=Haltedauer,L21+S21,0) -> -2734.9446
B22: 12 | C22: =Miete_Monat*12*(1+Mietsteigerung)^(B22-1) -> 14174.467 | D22: =-C22*Mietausfall -> -425.23401 | E22: =C22+D22 -> 13749.233 | F22: =-(Hausgeld_nu+Ruecklage+Verwaltung)*(1+Kostensteigerung)^(B22-1) -> -3096.002 | G22: =-Finanzierung!E31 -> -8164.4044 | H22: =-Finanzierung!F31 -> -5800.5956 | I22: =G22+H22 -> -13965 | J22: =E22+F22+I22 -> -3311.7689 | K22: =Steuern!J34 -> 572.75057 | L22: =J22+K22 -> -2739.0184 | M22: =SUM(L$11:L22) -> -29302.281 | N22: =Steuern!L34 -> 4900.4624 | O22: =Marktwert*(1+Wertsteigerung)^B22 -> 376667.81 | P22: =Finanzierung!H31 -> 175630.61 | Q22: =O22-P22 -> 201037.2 | R22: =IF(I22=0,"",(E22+F22)/-I22) -> 0.76285221 | S22: =IF(B22=Haltedauer,Exit_Netto,0) -> 189737.16 | T22: =IF(B22<=Haltedauer,L22+S22,0) -> 186998.15
... B40: 30 | C40: =Miete_Monat*12*(1+Mietsteigerung)^(B40-1) -> 20244.629 | D40: =-C40*Mietausfall -> -607.33888 | E40: =C40+D40 -> 19637.291 | F40: =-(Hausgeld_nu+Ruecklage+Verwaltung)*(1+Kostensteigerung)^(B40-1) -> -4421.8533 | G40: =-Finanzierung!E49 -> -1154.5079 | H40: =-Finanzierung!F49 -> -12810.492 | I40: =G40+H40 -> -13965 | J40: =E40+F40+I40 -> 1250.4373 | K40: =Steuern!J52 -> -4767.192 | L40: =J40+K40 -> -3516.7547 | M40: =SUM(L$11:L40) -> -83589.538 | N40: =Steuern!L52 -> 4900.4624 | O40: =Marktwert*(1+Wertsteigerung)^B40 -> 537974.39 | P40: =Finanzierung!H49 -> 12845.238 | Q40: =O40-P40 -> 525129.15 | R40: =IF(I40=0,"",(E40+F40)/-I40) -> 1.0895408 | S40: =IF(B40=Haltedauer,Exit_Netto,0) -> 0 | T40: =IF(B40<=Haltedauer,L40+S40,0) -> 0
B41: Gelb markiert: Verkaufsjahr (Haltedauer). Vorzeichen: Einnahmen positiv, Ausgaben negativ, Steuererstattung positiv.
B43: Exit-Rechnung | G43: Verkauf am Ende der Haltedauer | I43: Rendite-Kennzahlen
B44: Verkaufsjahr | F44: =Haltedauer -> 12 | I44: Bruttomietrendite (Sollmiete / Kaufpreis) | N44: =Miete_Monat*12/Kaufpreis -> 0.04
B45: Immobilienwert im Verkaufsjahr | F45: =INDEX(O11:O40,Haltedauer) -> 376667.81 | I45: Nettomietrendite (Reinertrag J1 / Gesamtinvestition) | N45: =(E11+F11)/Gesamtinvestition -> 0.026044572
B46: Verkaufskosten | F46: =-F45*Verkaufskosten -> -11300.034 | I46: Kapitaldienstdeckung Jahr 1 | N46: =R11 -> 0.61353383
B47: Ablösung Restschuld | F47: =-INDEX(P11:P40,Haltedauer) -> -175630.61 | I47: Cashflow n. St. / Monat – Jahr 1 | N47: =L11/12 -> 273.68543
B48: Steuerlicher Restbuchwert | F48: =AK_Immobilie+Inventar_AK+IF(Regel15_ok=1,0,Renovierung)-SUMPRODUCT((B11:B40<=Haltedauer)*N11:N40) -> 247473.35 | I48: Cashflow n. St. / Monat – Jahr 2 | N48: =L12/12 -> -251.90244
B49: Veräußerungsgewinn | F49: =F45+F46-F48 -> 117894.43 | I49: EK-Rendite Jahr 1 (inkl. Tilgung und Wertzuwachs) | N49: =(L11-H11+O11-O10)/Eigenkapital -> 0.1681966
B50: Steuer auf Veräußerungsgewinn (nur bis 10 Jahre) | F50: =-IF(Haltedauer<=10,MAX(0,F49)*Steuersatz_eff,0) -> 0 | I50: IRR nach Steuern | N50: =IRR(T10:T40,0.05) -> 0.051216806
B51: Netto-Exit-Erlös | F51: =F45+F46+F47+F50 -> 189737.16 | I51: Eigenkapital-Multiple | N51: =SUMIF(T10:T40,">0")/-SUMIF(T10:T40,"<0") -> 1.6717541
B52: Nicht berücksichtigt: Vorfälligkeitsentschädigung bei Verkauf während der Zinsbindung.
B54: Diagrammdaten Cockpit | G54: Cashflow Jahr 1 · € je Monat
B55: Miete | C55: =E11/12 -> 921.5
B56: Bewirt. | C56: =F11/12 -> -207.5
B57: Zinsen | C57: =G11/12 -> -755.41667
B58: Tilgung | C58: =H11/12 -> -408.33333
B59: vor St. | C59: =J11/12 -> -449.75
B60: Steuer | C60: =K11/12 -> 723.43543
B61: nach St. | C61: =L11/12 -> 273.68543
B63: Keine Gewähr. Ersetzt keine Rechts-, Steuer- oder Finanzberatung · Rechtsstand September 2026 | T63: MM Holding GmbH · Kornhausgasse 4 · 88250 Weingarten · HRB 750729

Sheet Finanzierung
B2: MM Holding | H2: Immobilien-Kalkulation · Version 2.0
B3: Finanzierung
B6: Start | C6: Leitfaden | D6: Cockpit | E6: Eingaben | F6: Projektion | G6: Finanzierung | H6: Steuern | I6: AfA-Vergleich | J6: Sensitivität | K6: Bankgespräch | L6: Hinweise | M6: Konfiguration
B8: Investitionsplan | F8: € · % v. Kaufpreis | I8: Finanzierungsplan
B9: Kaufpreis | E9: =Kaufpreis -> 285000 | F9: =E9/Kaufpreis -> 1 | I9: Darlehensbetrag | M9: =Darlehen -> 245000
B10: Grunderwerbsteuer (ohne bewegliche Gegenstände) | E10: =(Kaufpreis-Inventar)*GrESt_Satz -> 13850 | F10: =E10/Kaufpreis -> 0.048596491 | I10: Eigenkapitalbedarf | M10: =Gesamtinvestition-Darlehen -> 83974.5
B11: Notar | E11: =Kaufpreis*Notar_Satz -> 4275 | F11: =E11/Kaufpreis -> 0.015 | I11: Eigenkapitalquote | M11: =Eigenkapital/Gesamtinvestition -> 0.25526143
B12: Grundbuch | E12: =Kaufpreis*Grundbuch_Satz -> 1425 | F12: =E12/Kaufpreis -> 0.005 | I12: Beleihungsauslauf (Darlehen / Marktwert) | M12: =Darlehen/Marktwert -> 0.82491582
B13: Makler | E13: =Kaufpreis*Makler_Satz -> 10174.5 | F13: =E13/Kaufpreis -> 0.0357 | I13: Annuität p. a. (Zins + Tilgung) | M13: =Darlehen*(Zins+Tilgung) -> 13965
B14: Summe Kaufnebenkosten | E14: =SUM(E10:E13) -> 29724.5 | F14: =E14/Kaufpreis -> 0.10429649 | I14: Monatsrate | M14: =Annuitaet/12 -> 1163.75
B15: Renovierung / Erhaltungsaufwand | E15: =Renovierung -> 14250 | F15: =E15/Kaufpreis -> 0.05 | I15: Restschuld Ende Zinsbindung | M15: =INDEX($H$20:$H$49,Zinsbindung) -> 186982.02
B16: Gesamtinvestition | E16: =E9+E14+E15 -> 328974.5 | F16: =E16/Kaufpreis -> 1.1542965 | I16: Kaufpreisfaktor (Kaufpreis / Jahres-Sollmiete) | M16: =Kaufpreis/(Miete_Monat*12) -> 25
B18: Tilgungsplan | I18: € p. a. · jährliche Betrachtung
B19: Jahr | C19: Zinssatz | D19: Restschuld Anfang | E19: Zinsen | F19: Tilgung | G19: Kapitaldienst | H19: Restschuld Ende | I19: Phase
B20: 1 | C20: =IF(B20<=Zinsbindung,Zins,Anschlusszins) -> 0.037 | D20: =Darlehen -> 245000 | E20: =D20*C20 -> 9065 | F20: =MAX(0,MIN(Annuitaet-E20,D20)) -> 4900 | G20: =E20+F20 -> 13965 | H20: =D20-F20 -> 240100 | I20: =IF(B20<=Zinsbindung,"Zinsbindung","Anschluss") -> Zinsbindung
B21: 2 | C21: =IF(B21<=Zinsbindung,Zins,Anschlusszins) -> 0.037 | D21: =H20 -> 240100 | E21: =D21*C21 -> 8883.7 | F21: =MAX(0,MIN(Annuitaet-E21,D21)) -> 5081.3 | G21: =E21+F21 -> 13965 | H21: =D21-F21 -> 235018.7 | I21: =IF(B21<=Zinsbindung,"Zinsbindung","Anschluss") -> Zinsbindung
B22: 3 | C22: =IF(B22<=Zinsbindung,Zins,Anschlusszins) -> 0.037 | D22: =H21 -> 235018.7 | E22: =D22*C22 -> 8695.6919 | F22: =MAX(0,MIN(Annuitaet-E22,D22)) -> 5269.3081 | G22: =E22+F22 -> 13965 | H22: =D22-F22 -> 229749.39 | I22: =IF(B22<=Zinsbindung,"Zinsbindung","Anschluss") -> Zinsbindung
B23: 4 | C23: =IF(B23<=Zinsbindung,Zins,Anschlusszins) -> 0.037 | D23: =H22 -> 229749.39 | E23: =D23*C23 -> 8500.7275 | F23: =MAX(0,MIN(Annuitaet-E23,D23)) -> 5464.2725 | G23: =E23+F23 -> 13965 | H23: =D23-F23 -> 224285.12 | I23: =IF(B23<=Zinsbindung,"Zinsbindung","Anschluss") -> Zinsbindung
B24: 5 | C24: =IF(B24<=Zinsbindung,Zins,Anschlusszins) -> 0.037 | D24: =H23 -> 224285.12 | E24: =D24*C24 -> 8298.5494 | F24: =MAX(0,MIN(Annuitaet-E24,D24)) -> 5666.4506 | G24: =E24+F24 -> 13965 | H24: =D24-F24 -> 218618.67 | I24: =IF(B24<=Zinsbindung,"Zinsbindung","Anschluss") -> Zinsbindung
B25: 6 | C25: =IF(B25<=Zinsbindung,Zins,Anschlusszins) -> 0.037 | D25: =H24 -> 218618.67 | E25: =D25*C25 -> 8088.8907 | F25: =MAX(0,MIN(Annuitaet-E25,D25)) -> 5876.1093 | G25: =E25+F25 -> 13965 | H25: =D25-F25 -> 212742.56 | I25: =IF(B25<=Zinsbindung,"Zinsbindung","Anschluss") -> Zinsbindung
B26: 7 | C26: =IF(B26<=Zinsbindung,Zins,Anschlusszins) -> 0.037 | D26: =H25 -> 212742.56 | E26: =D26*C26 -> 7871.4747 | F26: =MAX(0,MIN(Annuitaet-E26,D26)) -> 6093.5253 | G26: =E26+F26 -> 13965 | H26: =D26-F26 -> 206649.03 | I26: =IF(B26<=Zinsbindung,"Zinsbindung","Anschluss") -> Zinsbindung
B27: 8 | C27: =IF(B27<=Zinsbindung,Zins,Anschlusszins) -> 0.037 | D27: =H26 -> 206649.03 | E27: =D27*C27 -> 7646.0143 | F27: =MAX(0,MIN(Annuitaet-E27,D27)) -> 6318.9857 | G27: =E27+F27 -> 13965 | H27: =D27-F27 -> 200330.05 | I27: =IF(B27<=Zinsbindung,"Zinsbindung","Anschluss") -> Zinsbindung
B28: 9 | C28: =IF(B28<=Zinsbindung,Zins,Anschlusszins) -> 0.037 | D28: =H27 -> 200330.05 | E28: =D28*C28 -> 7412.2118 | F28: =MAX(0,MIN(Annuitaet-E28,D28)) -> 6552.7882 | G28: =E28+F28 -> 13965 | H28: =D28-F28 -> 193777.26 | I28: =IF(B28<=Zinsbindung,"Zinsbindung","Anschluss") -> Zinsbindung
B29: 10 | C29: =IF(B29<=Zinsbindung,Zins,Anschlusszins) -> 0.037 | D29: =H28 -> 193777.26 | E29: =D29*C29 -> 7169.7586 | F29: =MAX(0,MIN(Annuitaet-E29,D29)) -> 6795.2414 | G29: =E29+F29 -> 13965 | H29: =D29-F29 -> 186982.02 | I29: =IF(B29<=Zinsbindung,"Zinsbindung","Anschluss") -> Zinsbindung
B30: 11 | C30: =IF(B30<=Zinsbindung,Zins,Anschlusszins) -> 0.045 | D30: =H29 -> 186982.02 | E30: =D30*C30 -> 8414.1909 | F30: =MAX(0,MIN(Annuitaet-E30,D30)) -> 5550.8091 | G30: =E30+F30 -> 13965 | H30: =D30-F30 -> 181431.21 | I30: =IF(B30<=Zinsbindung,"Zinsbindung","Anschluss") -> Anschluss
B31: 12 | C31: =IF(B31<=Zinsbindung,Zins,Anschlusszins) -> 0.045 | D31: =H30 -> 181431.21 | E31: =D31*C31 -> 8164.4044 | F31: =MAX(0,MIN(Annuitaet-E31,D31)) -> 5800.5956 | G31: =E31+F31 -> 13965 | H31: =D31-F31 -> 175630.61 | I31: =IF(B31<=Zinsbindung,"Zinsbindung","Anschluss") -> Anschluss
B32: 13 | C32: =IF(B32<=Zinsbindung,Zins,Anschlusszins) -> 0.045 | D32: =H31 -> 175630.61 | E32: =D32*C32 -> 7903.3776 | F32: =MAX(0,MIN(Annuitaet-E32,D32)) -> 6061.6224 | G32: =E32+F32 -> 13965 | H32: =D32-F32 -> 169568.99 | I32: =IF(B32<=Zinsbindung,"Zinsbindung","Anschluss") -> Anschluss
... B49: 30 | C49: =IF(B49<=Zinsbindung,Zins,Anschlusszins) -> 0.045 | D49: =H48 -> 25655.731 | E49: =D49*C49 -> 1154.5079 | F49: =MAX(0,MIN(Annuitaet-E49,D49)) -> 12810.492 | G49: =E49+F49 -> 13965 | H49: =D49-F49 -> 12845.238 | I49: =IF(B49<=Zinsbindung,"Zinsbindung","Anschluss") -> Anschluss
B51: Vereinfachung: Zinsen auf die Restschuld zu Jahresbeginn; bei monatlicher Zahlung fallen die Zinsen etwas geringer aus. Die Rate bleibt nach der Zinsbindung unverändert.
B53: Keine Gewähr. Ersetzt keine Rechts-, Steuer- oder Finanzberatung · Rechtsstand September 2026 | M53: MM Holding GmbH · Kornhausgasse 4 · 88250 Weingarten · HRB 750729

Sheet Steuern
B2: MM Holding | H2: Immobilien-Kalkulation · Version 2.0
B3: Steuern
B6: Start | C6: Leitfaden | D6: Cockpit | E6: Eingaben | F6: Projektion | G6: Finanzierung | H6: Steuern | I6: AfA-Vergleich | J6: Sensitivität | K6: Bankgespräch | L6: Hinweise | M6: Konfiguration
B8: AfA-Bemessungsgrundlage | G8: € | I8: 15-%-Grenze | M8: § 6 Abs. 1 Nr. 1a EStG
B9: Kaufpreis Immobilie (ohne bewegliche Gegenstände) | E9: =Kaufpreis-Inventar -> 277000 | I9: Anschaffungskosten Gebäude | M9: =Gebaeude_AK -> 245023.12
B10: Grunderwerbsteuer | E10: =Finanzierung!E10 -> 13850 | I10: Grenze: 15 % der Gebäude-AK | M10: =Gebaeude_AK*0.15 -> 36753.468
B11: Notar, Grundbuch, Makler (anteilig) | E11: =SUM(Finanzierung!E11:E13)*(Kaufpreis-Inventar)/Kaufpreis -> 15428.9 | I11: Renovierung netto (ersten 3 Jahre) | M11: =Renovierung -> 14250
B12: Anschaffungskosten Immobilie | E12: =SUM(E9:E11) -> 306278.9 | I12: Grenze eingehalten? | M12: =IF(Renovierung<=Grenze15,1,0) -> 1
B13: davon Grund und Boden (nicht abschreibbar) | E13: =AK_Immobilie*(1-Gebaeudeanteil) -> 61255.78 | I13: =IF(Regel15_ok=1,"Sofort abziehbarer Erhaltungsaufwand (ggf. verteilt nach § 82b EStDV).","Anschaffungsnahe Herstellungskosten – nur über die Gebäude-AfA absetzbar.") -> Sofort abziehbarer Erhaltungsaufwand (ggf. verteilt nach § 82b EStDV).
B14: davon Gebäude | E14: =AK_Immobilie*Gebaeudeanteil -> 245023.12
B15: zzgl. aktivierte Renovierung (bei Überschreiten der 15-%-Grenze) | E15: =IF(Regel15_ok=1,0,Renovierung) -> 0 | I15: Steuersatz
B16: AfA-Bemessungsgrundlage Gebäude | E16: =Gebaeude_AK+E15 -> 245023.12 | I16: Grenzsteuersatz Einkommensteuer | M16: =Grenzsteuersatz -> 0.42
B17: AfA Gebäude p. a. | E17: =AfA_Basis*AfA_Satz -> 4900.4624 | I17: Solidaritätszuschlag (auf ESt) | M17: =Soli -> 0.055
B18: Anschaffungskosten Inventar (inkl. anteiliger Nebenkosten) | E18: =Inventar+SUM(Finanzierung!E11:E13)*Inventar/Kaufpreis -> 8445.6 | I18: Kirchensteuer (auf ESt) | M18: =KiSt -> 0
B19: AfA Inventar p. a. | E19: =Inventar_AK/ND_Inventar -> 844.56 | I19: Effektiver Steuersatz | M19: =Grenzsteuersatz*(1+Soli+KiSt) -> 0.4431
B21: Einkünfte aus Vermietung und Verpachtung | L21: € p. a. · Erstattung positiv
B22: Jahr | C22: Mieteinnahmen | D22: Bewirtschaftung abziehbar | E22: Schuldzinsen | F22: AfA Gebäude | G22: AfA Inventar | H22: Erhaltungsaufwand | I22: Einkünfte V+V | J22: Steuereffekt | K22: Restbuchwert Gebäude | L22: Summe AfA
B23: 1 | C23: =Projektion!E11 -> 11058 | D23: =-(Hausgeld_nu+Verwaltung)*(1+Kostensteigerung)^(B23-1) -> -1590 | E23: =-Finanzierung!E20 -> -9065 | F23: =-MIN(AfA_Gebaeude,AfA_Basis+SUM(F$22:F22)) -> -4900.4624 | G23: =-IF(B23<=ND_Inventar,AfA_Inventar,0) -> -844.56 | H23: =-IF(AND(Regel15_ok=1,B23<=Erhaltung_Jahre),Renovierung/Erhaltung_Jahre,0) -> -14250 | I23: =SUM(C23:H23) -> -19592.022 | J23: =-I23*Steuersatz_eff -> 8681.2251 | K23: =AfA_Basis+SUM(F$23:F23) -> 240122.66 | L23: =-(F23+G23) -> 5745.0224
B24: 2 | C24: =Projektion!E12 -> 11279.16 | D24: =-(Hausgeld_nu+Verwaltung)*(1+Kostensteigerung)^(B24-1) -> -1621.8 | E24: =-Finanzierung!E21 -> -8883.7 | F24: =-MIN(AfA_Gebaeude,AfA_Basis+SUM(F$22:F23)) -> -4900.4624 | G24: =-IF(B24<=ND_Inventar,AfA_Inventar,0) -> -844.56 | H24: =-IF(AND(Regel15_ok=1,B24<=Erhaltung_Jahre),Renovierung/Erhaltung_Jahre,0) -> 0 | I24: =SUM(C24:H24) -> -4971.3624 | J24: =-I24*Steuersatz_eff -> 2202.8107 | K24: =AfA_Basis+SUM(F$23:F24) -> 235222.2 | L24: =-(F24+G24) -> 5745.0224
B25: 3 | C25: =Projektion!E13 -> 11504.743 | D25: =-(Hausgeld_nu+Verwaltung)*(1+Kostensteigerung)^(B25-1) -> -1654.236 | E25: =-Finanzierung!E22 -> -8695.6919 | F25: =-MIN(AfA_Gebaeude,AfA_Basis+SUM(F$22:F24)) -> -4900.4624 | G25: =-IF(B25<=ND_Inventar,AfA_Inventar,0) -> -844.56 | H25: =-IF(AND(Regel15_ok=1,B25<=Erhaltung_Jahre),Renovierung/Erhaltung_Jahre,0) -> 0 | I25: =SUM(C25:H25) -> -4590.2071 | J25: =-I25*Steuersatz_eff -> 2033.9208 | K25: =AfA_Basis+SUM(F$23:F25) -> 230321.73 | L25: =-(F25+G25) -> 5745.0224
B26: 4 | C26: =Projektion!E14 -> 11734.838 | D26: =-(Hausgeld_nu+Verwaltung)*(1+Kostensteigerung)^(B26-1) -> -1687.3207 | E26: =-Finanzierung!E23 -> -8500.7275 | F26: =-MIN(AfA_Gebaeude,AfA_Basis+SUM(F$22:F25)) -> -4900.4624 | G26: =-IF(B26<=ND_Inventar,AfA_Inventar,0) -> -844.56 | H26: =-IF(AND(Regel15_ok=1,B26<=Erhaltung_Jahre),Renovierung/Erhaltung_Jahre,0) -> 0 | I26: =SUM(C26:H26) -> -4198.2326 | J26: =-I26*Steuersatz_eff -> 1860.2368 | K26: =AfA_Basis+SUM(F$23:F26) -> 225421.27 | L26: =-(F26+G26) -> 5745.0224
B27: 5 | C27: =Projektion!E15 -> 11969.535 | D27: =-(Hausgeld_nu+Verwaltung)*(1+Kostensteigerung)^(B27-1) -> -1721.0671 | E27: =-Finanzierung!E24 -> -8298.5494 | F27: =-MIN(AfA_Gebaeude,AfA_Basis+SUM(F$22:F26)) -> -4900.4624 | G27: =-IF(B27<=ND_Inventar,AfA_Inventar,0) -> -844.56 | H27: =-IF(AND(Regel15_ok=1,B27<=Erhaltung_Jahre),Renovierung/Erhaltung_Jahre,0) -> 0 | I27: =SUM(C27:H27) -> -3795.1041 | J27: =-I27*Steuersatz_eff -> 1681.6106 | K27: =AfA_Basis+SUM(F$23:F27) -> 220520.81 | L27: =-(F27+G27) -> 5745.0224
B28: 6 | C28: =Projektion!E16 -> 12208.926 | D28: =-(Hausgeld_nu+Verwaltung)*(1+Kostensteigerung)^(B28-1) -> -1755.4885 | E28: =-Finanzierung!E25 -> -8088.8907 | F28: =-MIN(AfA_Gebaeude,AfA_Basis+SUM(F$22:F27)) -> -4900.4624 | G28: =-IF(B28<=ND_Inventar,AfA_Inventar,0) -> -844.56 | H28: =-IF(AND(Regel15_ok=1,B28<=Erhaltung_Jahre),Renovierung/Erhaltung_Jahre,0) -> 0 | I28: =SUM(C28:H28) -> -3380.4761 | J28: =-I28*Steuersatz_eff -> 1497.889 | K28: =AfA_Basis+SUM(F$23:F28) -> 215620.35 | L28: =-(F28+G28) -> 5745.0224
B29: 7 | C29: =Projektion!E17 -> 12453.104 | D29: =-(Hausgeld_nu+Verwaltung)*(1+Kostensteigerung)^(B29-1) -> -1790.5982 | E29: =-Finanzierung!E26 -> -7871.4747 | F29: =-MIN(AfA_Gebaeude,AfA_Basis+SUM(F$22:F28)) -> -4900.4624 | G29: =-IF(B29<=ND_Inventar,AfA_Inventar,0) -> -844.56 | H29: =-IF(AND(Regel15_ok=1,B29<=Erhaltung_Jahre),Renovierung/Erhaltung_Jahre,0) -> 0 | I29: =SUM(C29:H29) -> -2953.9913 | J29: =-I29*Steuersatz_eff -> 1308.9136 | K29: =AfA_Basis+SUM(F$23:F29) -> 210719.88 | L29: =-(F29+G29) -> 5745.0224
B30: 8 | C30: =Projektion!E18 -> 12702.166 | D30: =-(Hausgeld_nu+Verwaltung)*(1+Kostensteigerung)^(B30-1) -> -1826.4102 | E30: =-Finanzierung!E27 -> -7646.0143 | F30: =-MIN(AfA_Gebaeude,AfA_Basis+SUM(F$22:F29)) -> -4900.4624 | G30: =-IF(B30<=ND_Inventar,AfA_Inventar,0) -> -844.56 | H30: =-IF(AND(Regel15_ok=1,B30<=Erhaltung_Jahre),Renovierung/Erhaltung_Jahre,0) -> 0 | I30: =SUM(C30:H30) -> -2515.2808 | J30: =-I30*Steuersatz_eff -> 1114.5209 | K30: =AfA_Basis+SUM(F$23:F30) -> 205819.42 | L30: =-(F30+G30) -> 5745.0224
B31: 9 | C31: =Projektion!E19 -> 12956.209 | D31: =-(Hausgeld_nu+Verwaltung)*(1+Kostensteigerung)^(B31-1) -> -1862.9384 | E31: =-Finanzierung!E28 -> -7412.2118 | F31: =-MIN(AfA_Gebaeude,AfA_Basis+SUM(F$22:F30)) -> -4900.4624 | G31: =-IF(B31<=ND_Inventar,AfA_Inventar,0) -> -844.56 | H31: =-IF(AND(Regel15_ok=1,B31<=Erhaltung_Jahre),Renovierung/Erhaltung_Jahre,0) -> 0 | I31: =SUM(C31:H31) -> -2063.9632 | J31: =-I31*Steuersatz_eff -> 914.54208 | K31: =AfA_Basis+SUM(F$23:F31) -> 200918.96 | L31: =-(F31+G31) -> 5745.0224
B32: 10 | C32: =Projektion!E20 -> 13215.334 | D32: =-(Hausgeld_nu+Verwaltung)*(1+Kostensteigerung)^(B32-1) -> -1900.1972 | E32: =-Finanzierung!E29 -> -7169.7586 | F32: =-MIN(AfA_Gebaeude,AfA_Basis+SUM(F$22:F31)) -> -4900.4624 | G32: =-IF(B32<=ND_Inventar,AfA_Inventar,0) -> -844.56 | H32: =-IF(AND(Regel15_ok=1,B32<=Erhaltung_Jahre),Renovierung/Erhaltung_Jahre,0) -> 0 | I32: =SUM(C32:H32) -> -1599.6446 | J32: =-I32*Steuersatz_eff -> 708.80252 | K32: =AfA_Basis+SUM(F$23:F32) -> 196018.5 | L32: =-(F32+G32) -> 5745.0224
B33: 11 | C33: =Projektion!E21 -> 13479.64 | D33: =-(Hausgeld_nu+Verwaltung)*(1+Kostensteigerung)^(B33-1) -> -1938.2011 | E33: =-Finanzierung!E30 -> -8414.1909 | F33: =-MIN(AfA_Gebaeude,AfA_Basis+SUM(F$22:F32)) -> -4900.4624 | G33: =-IF(B33<=ND_Inventar,AfA_Inventar,0) -> 0 | H33: =-IF(AND(Regel15_ok=1,B33<=Erhaltung_Jahre),Renovierung/Erhaltung_Jahre,0) -> 0 | I33: =SUM(C33:H33) -> -1773.2141 | J33: =-I33*Steuersatz_eff -> 785.71116 | K33: =AfA_Basis+SUM(F$23:F33) -> 191118.03 | L33: =-(F33+G33) -> 4900.4624
B34: 12 | C34: =Projektion!E22 -> 13749.233 | D34: =-(Hausgeld_nu+Verwaltung)*(1+Kostensteigerung)^(B34-1) -> -1976.9652 | E34: =-Finanzierung!E31 -> -8164.4044 | F34: =-MIN(AfA_Gebaeude,AfA_Basis+SUM(F$22:F33)) -> -4900.4624 | G34: =-IF(B34<=ND_Inventar,AfA_Inventar,0) -> 0 | H34: =-IF(AND(Regel15_ok=1,B34<=Erhaltung_Jahre),Renovierung/Erhaltung_Jahre,0) -> 0 | I34: =SUM(C34:H34) -> -1292.5989 | J34: =-I34*Steuersatz_eff -> 572.75057 | K34: =AfA_Basis+SUM(F$23:F34) -> 186217.57 | L34: =-(F34+G34) -> 4900.4624
... B52: 30 | C52: =Projektion!E40 -> 19637.291 | D52: =-(Hausgeld_nu+Verwaltung)*(1+Kostensteigerung)^(B52-1) -> -2823.5931 | E52: =-Finanzierung!E49 -> -1154.5079 | F52: =-MIN(AfA_Gebaeude,AfA_Basis+SUM(F$22:F51)) -> -4900.4624 | G52: =-IF(B52<=ND_Inventar,AfA_Inventar,0) -> 0 | H52: =-IF(AND(Regel15_ok=1,B52<=Erhaltung_Jahre),Renovierung/Erhaltung_Jahre,0) -> 0 | I52: =SUM(C52:H52) -> 10758.727 | J52: =-I52*Steuersatz_eff -> -4767.192 | K52: =AfA_Basis+SUM(F$23:F52) -> 98009.248 | L52: =-(F52+G52) -> 4900.4624
B54: Annahmen: Verluste werden vollständig mit anderen Einkünften verrechnet; Steuersatz vereinfacht als Grenzsteuersatz × (1 + Soli + Kirchensteuer). Instandhaltungsrücklage erst bei Verwendung abziehbar.
B56: Keine Gewähr. Ersetzt keine Rechts-, Steuer- oder Finanzberatung · Rechtsstand September 2026 | M56: MM Holding GmbH · Kornhausgasse 4 · 88250 Weingarten · HRB 750729

Sheet AfA-Vergleich
B2: MM Holding | H2: Immobilien-Kalkulation · Version 2.0
B3: AfA-Vergleich
B6: Start | C6: Leitfaden | D6: Cockpit | E6: Eingaben | F6: Projektion | G6: Finanzierung | H6: Steuern | I6: AfA-Vergleich | J6: Sensitivität | K6: Bankgespräch | L6: Hinweise | M6: Konfiguration
B8: Vergleich der Abschreibungsmethoden | K8: Bemessungsgrundlage: Gebäude
D9: Linear 2,0 % | E9: Linear 2,5 % | F9: Linear 3,0 % | G9: Degressiv 5,0 % | H9: Hinweis
B10: AfA-Satz | D10: 0.02 | E10: 0.025 | F10: 0.03 | G10: 0.05 | H10: Gesetzliche Sätze nach § 7 Abs. 4 und 5a EStG
B11: Voraussetzung | D11: Fertigst. 1925–2022 | E11: Fertigst. vor 1925 | F11: Fertigst. ab 2023 | G11: Neubau, Baubeginn 10/2023–9/2029 | H11: Degressiv: jährlich 5 % vom Restbuchwert, Wechsel zu linear möglich (hier nicht modelliert)
B12: AfA Jahr 1 | D12: =D20 -> 4900.4624 | E12: =E20 -> 6125.578 | F12: =F20 -> 7350.6936 | G12: =G20 -> 12251.156
B13: Summe AfA bis Verkauf | D13: =SUMPRODUCT(($B$20:$B$49<=Haltedauer)*D$20:D$49) -> 58805.549 | E13: =SUMPRODUCT(($B$20:$B$49<=Haltedauer)*E$20:E$49) -> 73506.936 | F13: =SUMPRODUCT(($B$20:$B$49<=Haltedauer)*F$20:F$49) -> 88208.323 | G13: =SUMPRODUCT(($B$20:$B$49<=Haltedauer)*G$20:G$49) -> 112622.41 | H13: Höhere AfA erhöht beim Verkauf innerhalb von 10 Jahren den steuerpflichtigen Gewinn.
B14: Steuerersparnis bis Verkauf | D14: =D13*Steuersatz_eff -> 26056.739 | E14: =E13*Steuersatz_eff -> 32570.923 | F14: =F13*Steuersatz_eff -> 39085.108 | G14: =G13*Steuersatz_eff -> 49902.988
B15: Restbuchwert bei Verkauf | D15: =AfA_Basis-D13 -> 186217.57 | E15: =AfA_Basis-E13 -> 171516.18 | F15: =AfA_Basis-F13 -> 156814.8 | G15: =AfA_Basis-G13 -> 132400.71
B16: In „Eingaben“ gewählt | D16: =IF(ROUND(AfA_Satz,4)=ROUND(D10,4),"✓ gewählt","") -> ✓ gewählt | E16: =IF(ROUND(AfA_Satz,4)=ROUND(E10,4),"✓ gewählt","") | F16: =IF(ROUND(AfA_Satz,4)=ROUND(F10,4),"✓ gewählt","") | G16: =IF(ROUND(AfA_Satz,4)=ROUND(G10,4),"✓ gewählt","")
B18: Jahreswerte | K18: € p. a.
B19: Jahr | D19: AfA 2,0 % | E19: AfA 2,5 % | F19: AfA 3,0 % | G19: AfA degr. 5 % | H19: RBW 2,0 % | I19: RBW 2,5 % | J19: RBW 3,0 % | K19: RBW degr.
B20: 1 | D20: =MIN(D$10*AfA_Basis,AfA_Basis-SUM(D$19:D19)) -> 4900.4624 | E20: =MIN(E$10*AfA_Basis,AfA_Basis-SUM(E$19:E19)) -> 6125.578 | F20: =MIN(F$10*AfA_Basis,AfA_Basis-SUM(F$19:F19)) -> 7350.6936 | G20: =(AfA_Basis-SUM(G$19:G19))*G$10 -> 12251.156 | H20: =AfA_Basis-SUM(D$20:D20) -> 240122.66 | I20: =AfA_Basis-SUM(E$20:E20) -> 238897.54 | J20: =AfA_Basis-SUM(F$20:F20) -> 237672.43 | K20: =AfA_Basis-SUM(G$20:G20) -> 232771.96
B21: 2 | D21: =MIN(D$10*AfA_Basis,AfA_Basis-SUM(D$19:D20)) -> 4900.4624 | E21: =MIN(E$10*AfA_Basis,AfA_Basis-SUM(E$19:E20)) -> 6125.578 | F21: =MIN(F$10*AfA_Basis,AfA_Basis-SUM(F$19:F20)) -> 7350.6936 | G21: =(AfA_Basis-SUM(G$19:G20))*G$10 -> 11638.598 | H21: =AfA_Basis-SUM(D$20:D21) -> 235222.2 | I21: =AfA_Basis-SUM(E$20:E21) -> 232771.96 | J21: =AfA_Basis-SUM(F$20:F21) -> 230321.73 | K21: =AfA_Basis-SUM(G$20:G21) -> 221133.37
B22: 3 | D22: =MIN(D$10*AfA_Basis,AfA_Basis-SUM(D$19:D21)) -> 4900.4624 | E22: =MIN(E$10*AfA_Basis,AfA_Basis-SUM(E$19:E21)) -> 6125.578 | F22: =MIN(F$10*AfA_Basis,AfA_Basis-SUM(F$19:F21)) -> 7350.6936 | G22: =(AfA_Basis-SUM(G$19:G21))*G$10 -> 11056.668 | H22: =AfA_Basis-SUM(D$20:D22) -> 230321.73 | I22: =AfA_Basis-SUM(E$20:E22) -> 226646.39 | J22: =AfA_Basis-SUM(F$20:F22) -> 222971.04 | K22: =AfA_Basis-SUM(G$20:G22) -> 210076.7
B23: 4 | D23: =MIN(D$10*AfA_Basis,AfA_Basis-SUM(D$19:D22)) -> 4900.4624 | E23: =MIN(E$10*AfA_Basis,AfA_Basis-SUM(E$19:E22)) -> 6125.578 | F23: =MIN(F$10*AfA_Basis,AfA_Basis-SUM(F$19:F22)) -> 7350.6936 | G23: =(AfA_Basis-SUM(G$19:G22))*G$10 -> 10503.835 | H23: =AfA_Basis-SUM(D$20:D23) -> 225421.27 | I23: =AfA_Basis-SUM(E$20:E23) -> 220520.81 | J23: =AfA_Basis-SUM(F$20:F23) -> 215620.35 | K23: =AfA_Basis-SUM(G$20:G23) -> 199572.86
B24: 5 | D24: =MIN(D$10*AfA_Basis,AfA_Basis-SUM(D$19:D23)) -> 4900.4624 | E24: =MIN(E$10*AfA_Basis,AfA_Basis-SUM(E$19:E23)) -> 6125.578 | F24: =MIN(F$10*AfA_Basis,AfA_Basis-SUM(F$19:F23)) -> 7350.6936 | G24: =(AfA_Basis-SUM(G$19:G23))*G$10 -> 9978.6431 | H24: =AfA_Basis-SUM(D$20:D24) -> 220520.81 | I24: =AfA_Basis-SUM(E$20:E24) -> 214395.23 | J24: =AfA_Basis-SUM(F$20:F24) -> 208269.65 | K24: =AfA_Basis-SUM(G$20:G24) -> 189594.22
B25: 6 | D25: =MIN(D$10*AfA_Basis,AfA_Basis-SUM(D$19:D24)) -> 4900.4624 | E25: =MIN(E$10*AfA_Basis,AfA_Basis-SUM(E$19:E24)) -> 6125.578 | F25: =MIN(F$10*AfA_Basis,AfA_Basis-SUM(F$19:F24)) -> 7350.6936 | G25: =(AfA_Basis-SUM(G$19:G24))*G$10 -> 9479.711 | H25: =AfA_Basis-SUM(D$20:D25) -> 215620.35 | I25: =AfA_Basis-SUM(E$20:E25) -> 208269.65 | J25: =AfA_Basis-SUM(F$20:F25) -> 200918.96 | K25: =AfA_Basis-SUM(G$20:G25) -> 180114.51
B26: 7 | D26: =MIN(D$10*AfA_Basis,AfA_Basis-SUM(D$19:D25)) -> 4900.4624 | E26: =MIN(E$10*AfA_Basis,AfA_Basis-SUM(E$19:E25)) -> 6125.578 | F26: =MIN(F$10*AfA_Basis,AfA_Basis-SUM(F$19:F25)) -> 7350.6936 | G26: =(AfA_Basis-SUM(G$19:G25))*G$10 -> 9005.7254 | H26: =AfA_Basis-SUM(D$20:D26) -> 210719.88 | I26: =AfA_Basis-SUM(E$20:E26) -> 202144.07 | J26: =AfA_Basis-SUM(F$20:F26) -> 193568.26 | K26: =AfA_Basis-SUM(G$20:G26) -> 171108.78
B27: 8 | D27: =MIN(D$10*AfA_Basis,AfA_Basis-SUM(D$19:D26)) -> 4900.4624 | E27: =MIN(E$10*AfA_Basis,AfA_Basis-SUM(E$19:E26)) -> 6125.578 | F27: =MIN(F$10*AfA_Basis,AfA_Basis-SUM(F$19:F26)) -> 7350.6936 | G27: =(AfA_Basis-SUM(G$19:G26))*G$10 -> 8555.4392 | H27: =AfA_Basis-SUM(D$20:D27) -> 205819.42 | I27: =AfA_Basis-SUM(E$20:E27) -> 196018.5 | J27: =AfA_Basis-SUM(F$20:F27) -> 186217.57 | K27: =AfA_Basis-SUM(G$20:G27) -> 162553.34
B28: 9 | D28: =MIN(D$10*AfA_Basis,AfA_Basis-SUM(D$19:D27)) -> 4900.4624 | E28: =MIN(E$10*AfA_Basis,AfA_Basis-SUM(E$19:E27)) -> 6125.578 | F28: =MIN(F$10*AfA_Basis,AfA_Basis-SUM(F$19:F27)) -> 7350.6936 | G28: =(AfA_Basis-SUM(G$19:G27))*G$10 -> 8127.6672 | H28: =AfA_Basis-SUM(D$20:D28) -> 200918.96 | I28: =AfA_Basis-SUM(E$20:E28) -> 189892.92 | J28: =AfA_Basis-SUM(F$20:F28) -> 178866.88 | K28: =AfA_Basis-SUM(G$20:G28) -> 154425.68
B29: 10 | D29: =MIN(D$10*AfA_Basis,AfA_Basis-SUM(D$19:D28)) -> 4900.4624 | E29: =MIN(E$10*AfA_Basis,AfA_Basis-SUM(E$19:E28)) -> 6125.578 | F29: =MIN(F$10*AfA_Basis,AfA_Basis-SUM(F$19:F28)) -> 7350.6936 | G29: =(AfA_Basis-SUM(G$19:G28))*G$10 -> 7721.2838 | H29: =AfA_Basis-SUM(D$20:D29) -> 196018.5 | I29: =AfA_Basis-SUM(E$20:E29) -> 183767.34 | J29: =AfA_Basis-SUM(F$20:F29) -> 171516.18 | K29: =AfA_Basis-SUM(G$20:G29) -> 146704.39
B30: 11 | D30: =MIN(D$10*AfA_Basis,AfA_Basis-SUM(D$19:D29)) -> 4900.4624 | E30: =MIN(E$10*AfA_Basis,AfA_Basis-SUM(E$19:E29)) -> 6125.578 | F30: =MIN(F$10*AfA_Basis,AfA_Basis-SUM(F$19:F29)) -> 7350.6936 | G30: =(AfA_Basis-SUM(G$19:G29))*G$10 -> 7335.2196 | H30: =AfA_Basis-SUM(D$20:D30) -> 191118.03 | I30: =AfA_Basis-SUM(E$20:E30) -> 177641.76 | J30: =AfA_Basis-SUM(F$20:F30) -> 164165.49 | K30: =AfA_Basis-SUM(G$20:G30) -> 139369.17
B31: 12 | D31: =MIN(D$10*AfA_Basis,AfA_Basis-SUM(D$19:D30)) -> 4900.4624 | E31: =MIN(E$10*AfA_Basis,AfA_Basis-SUM(E$19:E30)) -> 6125.578 | F31: =MIN(F$10*AfA_Basis,AfA_Basis-SUM(F$19:F30)) -> 7350.6936 | G31: =(AfA_Basis-SUM(G$19:G30))*G$10 -> 6968.4587 | H31: =AfA_Basis-SUM(D$20:D31) -> 186217.57 | I31: =AfA_Basis-SUM(E$20:E31) -> 171516.18 | J31: =AfA_Basis-SUM(F$20:F31) -> 156814.8 | K31: =AfA_Basis-SUM(G$20:G31) -> 132400.71
... B49: 30 | D49: =MIN(D$10*AfA_Basis,AfA_Basis-SUM(D$19:D48)) -> 4900.4624 | E49: =MIN(E$10*AfA_Basis,AfA_Basis-SUM(E$19:E48)) -> 6125.578 | F49: =MIN(F$10*AfA_Basis,AfA_Basis-SUM(F$19:F48)) -> 7350.6936 | G49: =(AfA_Basis-SUM(G$19:G48))*G$10 -> 2767.9716 | H49: =AfA_Basis-SUM(D$20:D49) -> 98009.248 | I49: =AfA_Basis-SUM(E$20:E49) -> 61255.78 | J49: =AfA_Basis-SUM(F$20:F49) -> 24502.312 | K49: =AfA_Basis-SUM(G$20:G49) -> 52591.46
B50: RBW = Restbuchwert. Gelb markiert: Verkaufsjahr.
B52: Keine Gewähr. Ersetzt keine Rechts-, Steuer- oder Finanzberatung · Rechtsstand September 2026 | M52: MM Holding GmbH · Kornhausgasse 4 · 88250 Weingarten · HRB 750729

Sheet Sensitivität
B2: MM Holding | H2: Immobilien-Kalkulation · Version 2.0
B3: Sensitivität
B6: Start | C6: Leitfaden | D6: Cockpit | E6: Eingaben | F6: Projektion | G6: Finanzierung | H6: Steuern | I6: AfA-Vergleich | J6: Sensitivität | K6: Bankgespräch | L6: Hinweise | M6: Konfiguration
B8: Basiswerte Jahr 1 | G8: aus Eingaben und Steuern
B9: Jahres-Sollmiete | F9: =Miete_Monat*12 -> 11400 | I9: Blau: Variationsschritte – frei änderbar.
B10: Bewirtschaftung gesamt (liquiditätswirksam) | F10: =Hausgeld_nu+Ruecklage+Verwaltung -> 2490 | I10: Mittelfeld = Basisfall (entspricht Projektion Jahr 1).
B11: davon steuerlich abziehbar | F11: =Hausgeld_nu+Verwaltung -> 1590
B12: AfA und Erhaltungsaufwand Jahr 1 | F12: =-(Steuern!F23+Steuern!G23+Steuern!H23) -> 19995.022
B15: Cashflow nach Steuern je Monat – Jahr 1 | I15: € / Monat
D16: Änderung Nettokaltmiete
B17: Sollzins | C17: Δ Zins | D17: -0.1 | E17: -0.05 | F17: 0 | G17: 0.05 | H17: 0.1
B18: =Zins+C18 -> 0.027 | C18: -0.01 | D18: =(($F$9*(1+D$17)*(1-Mietausfall))-$F$10-(Darlehen*(Zins+$C18))-(Darlehen*Tilgung)-(($F$9*(1+D$17)*(1-Mietausfall))-$F$11-(Darlehen*(Zins+$C18))-$F$12)*Steuersatz_eff)/12 -> 336.06751 | E18: =(($F$9*(1+E$17)*(1-Mietausfall))-$F$10-(Darlehen*(Zins+$C18))-(Darlehen*Tilgung)-(($F$9*(1+E$17)*(1-Mietausfall))-$F$11-(Darlehen*(Zins+$C18))-$F$12)*Steuersatz_eff)/12 -> 361.72668 | F18: =(($F$9*(1+F$17)*(1-Mietausfall))-$F$10-(Darlehen*(Zins+$C18))-(Darlehen*Tilgung)-(($F$9*(1+F$17)*(1-Mietausfall))-$F$11-(Darlehen*(Zins+$C18))-$F$12)*Steuersatz_eff)/12 -> 387.38584 | G18: =(($F$9*(1+G$17)*(1-Mietausfall))-$F$10-(Darlehen*(Zins+$C18))-(Darlehen*Tilgung)-(($F$9*(1+G$17)*(1-Mietausfall))-$F$11-(Darlehen*(Zins+$C18))-$F$12)*Steuersatz_eff)/12 -> 413.04501 | H18: =(($F$9*(1+H$17)*(1-Mietausfall))-$F$10-(Darlehen*(Zins+$C18))-(Darlehen*Tilgung)-(($F$9*(1+H$17)*(1-Mietausfall))-$F$11-(Darlehen*(Zins+$C18))-$F$12)*Steuersatz_eff)/12 -> 438.70418
B19: =Zins+C19 -> 0.032 | C19: -0.005 | D19: =(($F$9*(1+D$17)*(1-Mietausfall))-$F$10-(Darlehen*(Zins+$C19))-(Darlehen*Tilgung)-(($F$9*(1+D$17)*(1-Mietausfall))-$F$11-(Darlehen*(Zins+$C19))-$F$12)*Steuersatz_eff)/12 -> 279.2173 | E19: =(($F$9*(1+E$17)*(1-Mietausfall))-$F$10-(Darlehen*(Zins+$C19))-(Darlehen*Tilgung)-(($F$9*(1+E$17)*(1-Mietausfall))-$F$11-(Darlehen*(Zins+$C19))-$F$12)*Steuersatz_eff)/12 -> 304.87647 | F19: =(($F$9*(1+F$17)*(1-Mietausfall))-$F$10-(Darlehen*(Zins+$C19))-(Darlehen*Tilgung)-(($F$9*(1+F$17)*(1-Mietausfall))-$F$11-(Darlehen*(Zins+$C19))-$F$12)*Steuersatz_eff)/12 -> 330.53564 | G19: =(($F$9*(1+G$17)*(1-Mietausfall))-$F$10-(Darlehen*(Zins+$C19))-(Darlehen*Tilgung)-(($F$9*(1+G$17)*(1-Mietausfall))-$F$11-(Darlehen*(Zins+$C19))-$F$12)*Steuersatz_eff)/12 -> 356.1948 | H19: =(($F$9*(1+H$17)*(1-Mietausfall))-$F$10-(Darlehen*(Zins+$C19))-(Darlehen*Tilgung)-(($F$9*(1+H$17)*(1-Mietausfall))-$F$11-(Darlehen*(Zins+$C19))-$F$12)*Steuersatz_eff)/12 -> 381.85397
